Workbook

Sheet README
A1: HGT Inventory Control System — How This Workbook Works
A2: Rebuilt from STOCK REPORT RECONCILED latest one.xlsx on the fixes identified in the stock report audit.
A4: What changed vs. the old file
A5: 1. One fixed layout for every week tab — same columns, same order, same header row, every time.
A6: 2. Opening stock for each week is a formula linking to the PRIOR week’s closing stock — never retyped.
A7: 3. Stock In Dodoma is now included in every closing-stock formula (it was silently dropped before).
A8: 4. No formulas were replaced with typed numbers — every closing/total cell recalculates.
A9: 5. Each SKU (Product + Pack Size + Type) has exactly one home row in every week, so nothing is split.
A10: 6. Any week where recorded sales/out exceed recorded stock now shows in the Stock Alert column instead of silently going negative.
A11: 7. Branch distribution (Dar / Dodoma / Iringa / Manyara: sent, sold, not sold) is tracked every week in its own block.
A13: Color legend
A14: Blue text = a manually entered number (opening baseline the week a product started, sales, stock in/out, sent/sold, remarks).
... A35: Row 201 totals imports by origin for the week. Duplicate this tab for future weeks so the columns carry forward.

Sheet Dashboard
A1: HGT Inventory Dashboard
A2: Live KPIs pulled from Master Products and each week tab. Recalculates automatically as you fill in new weeks.
A4: Total SKUs tracked | C4: =COUNTA('Master Products'!A5:A201) -> 197
A5: SKUs below reorder point | C5: =COUNTIF('Master Products'!G5:G201,"REORDER") -> 0
A6: SKUs with negative stock | C6: =COUNTIF('Master Products'!G5:G201,"NEGATIVE - CHECK ENTRIES") -> 0
A7: SKUs OK | C7: =COUNTIF('Master Products'!G5:G201,"OK") -> 0
A10: Total warehouse stock by week (Arusha + Moro + Dar)
A11: Week | B11: Total Closing Stock
A12: 26 june | B12: =SUM('26 june'!T3:V199) -> 12222
A13: 3-july2026 | B13: =SUM('3-july2026'!T3:V199) -> 11547
A14: 10-JULY2026 | B14: =SUM('10-JULY2026'!T3:V199) -> 11243
A15: 17-july2026 | B15: =SUM('17-july2026'!T3:V199) -> 10395
A16: 24-july-2026 | B16: =SUM('24-july-2026'!T3:V199) -> 22568
A17: 31-july-2026 | B17: =SUM('31-july-2026'!T3:V199) -> 19078
A18: 8-august-2026 | B18: =SUM('8-august-2026'!T3:V199) -> 18321
A19: 15-august-2026 | B19: =SUM('15-august-2026'!T3:V199) -> 16777
A20: 21-AUGUST-2026 | B20: =SUM('21-AUGUST-2026'!T3:V199) -> 15770
A21: 29-AUGUST-2026 | B21: =SUM('5-SEPTEMBER-2026'!Y3:Z198) -> 21401

Sheet Master Products
A1: Master Product List
A2: One row per SKU. Reorder Point is the only cell you edit here — everything else pulls live from the latest week tab.
A4: Product | B4: Pack Size | C4: Category | D4: Type | E4: Reorder Point (edit me) | F4: Current Stock (29-AUGUST-2026) | G4: Status | H4: Last Updated
A5: 30-WC773 | B5: 1000 | C5: SEED | D5: COMMERCIAL | F5: ='5-SEPTEMBER-2026'!Y3+'5-SEPTEMBER-2026'!Z3+'5-SEPTEMBER-2026'!#REF! -> #REF! | G5: =IF(F5<0,"NEGATIVE - CHECK ENTRIES",IF(AND(E5<>"",E5>0,F5<=E5),"REORDER","OK")) -> #REF! | H5: 29-AUGUST-2026
A6: Afadja | B6: 500 | C6: SEED | D6: CUSTOM&TRIAL | F6: ='5-SEPTEMBER-2026'!Y4+'5-SEPTEMBER-2026'!Z4+'5-SEPTEMBER-2026'!#REF! -> #REF! | G6: =IF(F6<0,"NEGATIVE - CHECK ENTRIES",IF(AND(E6<>"",E6>0,F6<=E6),"REORDER","OK")) -> #REF! | H6: 29-AUGUST-2026
A7: African eggplant BENUE F1 | B7: 100 | C7: SEED | D7: COMMERCIAL | F7: ='5-SEPTEMBER-2026'!Y5+'5-SEPTEMBER-2026'!Z5+'5-SEPTEMBER-2026'!#REF! -> #REF! | G7: =IF(F7<0,"NEGATIVE - CHECK ENTRIES",IF(AND(E7<>"",E7>0,F7<=E7),"REORDER","OK")) -> #REF! | H7: 29-AUGUST-2026
A8: African eggplant KAZINGA RZ F1 | B8: 100 | C8: SEED | D8: COMMERCIAL | F8: ='5-SEPTEMBER-2026'!Y6+'5-SEPTEMBER-2026'!Z6+'5-SEPTEMBER-2026'!#REF! -> #REF! | G8: =IF(F8<0,"NEGATIVE - CHECK ENTRIES",IF(AND(E8<>"",E8>0,F8<=E8),"REORDER","OK")) -> #REF! | H8: 29-AUGUST-2026
A9: African eggplant KERIO RZ F1 | B9: 100 | C9: SEED | D9: COMMERCIAL | F9: ='5-SEPTEMBER-2026'!Y7+'5-SEPTEMBER-2026'!Z7+'5-SEPTEMBER-2026'!#REF! -> #REF! | G9: =IF(F9<0,"NEGATIVE - CHECK ENTRIES",IF(AND(E9<>"",E9>0,F9<=E9),"REORDER","OK")) -> #REF! | H9: 29-AUGUST-2026
A10: African eggplant LIMPOPO RZ F3 | B10: 100 | C10: SEED | D10: COMMERCIAL | F10: ='5-SEPTEMBER-2026'!Y8+'5-SEPTEMBER-2026'!Z8+'5-SEPTEMBER-2026'!#REF! -> #REF! | G10: =IF(F10<0,"NEGATIVE - CHECK ENTRIES",IF(AND(E10<>"",E10>0,F10<=E10),"REORDER","OK")) -> #REF! | H10: 29-AUGUST-2026
A11: African hot pepper AFADJA RZ F7 | B11: 100 | C11: SEED | D11: COMMERCIAL | F11: ='5-SEPTEMBER-2026'!Y9+'5-SEPTEMBER-2026'!Z9+'5-SEPTEMBER-2026'!#REF! -> #REF! | G11: =IF(F11<0,"NEGATIVE - CHECK ENTRIES",IF(AND(E11<>"",E11>0,F11<=E11),"REORDER","OK")) -> #REF! | H11: 29-AUGUST-2026
A12: African hot pepper AFADJA RZ F7 | B12: 500 | C12: SEED | D12: COMMERCIAL | F12: ='5-SEPTEMBER-2026'!Y10+'5-SEPTEMBER-2026'!Z10+'5-SEPTEMBER-2026'!#REF! -> #REF! | G12: =IF(F12<0,"NEGATIVE - CHECK ENTRIES",IF(AND(E12<>"",E12>0,F12<=E12),"REORDER","OK")) -> #REF! | H12: 29-AUGUST-2026
A13: African hot pepper LENGAI RZ F2 | B13: 100 | C13: SEED | D13: COMMERCIAL | F13: ='5-SEPTEMBER-2026'!Y11+'5-SEPTEMBER-2026'!Z11+'5-SEPTEMBER-2026'!#REF! -> #REF! | G13: =IF(F13<0,"NEGATIVE - CHECK ENTRIES",IF(AND(E13<>"",E13>0,F13<=E13),"REORDER","OK")) -> #REF! | H13: 29-AUGUST-2026
A14: African hot pepper LENGAI RZ F3 | B14: 500 | C14: SEED | D14: COMMERCIAL | F14: ='5-SEPTEMBER-2026'!Y12+'5-SEPTEMBER-2026'!Z12+'5-SEPTEMBER-2026'!#REF! -> #REF! | G14: =IF(F14<0,"NEGATIVE - CHECK ENTRIES",IF(AND(E14<>"",E14>0,F14<=E14),"REORDER","OK")) -> #REF! | H14: 29-AUGUST-2026
A15: African Hot Pepper Loleza RZ | B15: 100 | C15: SEED | D15: COMMERCIAL | F15: ='5-SEPTEMBER-2026'!Y13+'5-SEPTEMBER-2026'!Z13+'5-SEPTEMBER-2026'!#REF! -> #REF! | G15: =IF(F15<0,"NEGATIVE - CHECK ENTRIES",IF(AND(E15<>"",E15>0,F15<=E15),"REORDER","OK")) -> #REF! | H15: 29-AUGUST-2026
A16: African Hot Pepper Loleza RZ | B16: 500 | C16: SEED | D16: COMMERCIAL | F16: ='5-SEPTEMBER-2026'!Y14+'5-SEPTEMBER-2026'!Z14+'5-SEPTEMBER-2026'!#REF! -> #REF! | G16: =IF(F16<0,"NEGATIVE - CHECK ENTRIES",IF(AND(E16<>"",E16>0,F16<=E16),"REORDER","OK")) -> #REF! | H16: 29-AUGUST-2026
... A38: Blanched celery KYLIAN RZ | B38: 1000 | C38: SEED | D38: COMMERCIAL | F38: ='5-SEPTEMBER-2026'!Y36+'5-SEPTEMBER-2026'!Z36+'5-SEPTEMBER-2026'!#REF! -> #REF! | G38: =IF(F38<0,"NEGATIVE - CHECK ENTRIES",IF(AND(E38<>"",E38>0,F38<=E38),"REORDER","OK")) -> #REF! | H38: 29-AUGUST-2026
A39: Boelli | B39: 1000 | C39: SEED | D39: MASIFIO CUSTOM | F39: ='5-SEPTEMBER-2026'!Y38+'5-SEPTEMBER-2026'!Z38+'5-SEPTEMBER-2026'!#REF! -> #REF! | G39: =IF(F39<0,"NEGATIVE - CHECK ENTRIES",IF(AND(E39<>"",E39>0,F39<=E39),"REORDER","OK")) -> #REF! | H39: 29-AUGUST-2026
A40: Bologna | B40: 100 | C40: SEED | D40: CUSTOM&TRIAL | F40: ='5-SEPTEMBER-2026'!Y39+'5-SEPTEMBER-2026'!Z39+'5-SEPTEMBER-2026'!#REF! -> #REF! | G40: =IF(F40<0,"NEGATIVE - CHECK ENTRIES",IF(AND(E40<>"",E40>0,F40<=E40),"REORDER","OK")) -> #REF! | H40: 29-AUGUST-2026
A41: Bottas | B41: 100000 | C41: SEED | D41: MASIFIO CUSTOM | F41: ='5-SEPTEMBER-2026'!Y40+'5-SEPTEMBER-2026'!Z40+'5-SEPTEMBER-2026'!#REF! -> #REF! | G41: =IF(F41<0,"NEGATIVE - CHECK ENTRIES",IF(AND(E41<>"",E41>0,F41<=E41),"REORDER","OK")) -> #REF! | H41: 29-AUGUST-2026
A42: Bourdais | B42: 100000 | C42: SEED | D42: MASIFIO CUSTOM | F42: ='5-SEPTEMBER-2026'!Y41+'5-SEPTEMBER-2026'!Z41+'5-SEPTEMBER-2026'!#REF! -> #REF! | G42: =IF(F42<0,"NEGATIVE - CHECK ENTRIES",IF(AND(E42<>"",E42>0,F42<=E42),"REORDER","OK")) -> #REF! | H42: 29-AUGUST-2026
A43: Bravura | B43: 100 | C43: SEED | D43: COMMERCIAL | F43: ='5-SEPTEMBER-2026'!Y42+'5-SEPTEMBER-2026'!Z42+'5-SEPTEMBER-2026'!#REF! -> #REF! | G43: =IF(F43<0,"NEGATIVE - CHECK ENTRIES",IF(AND(E43<>"",E43>0,F43<=E43),"REORDER","OK")) -> #REF! | H43: 29-AUGUST-2026
A44: Brigitte | B44: 100 | C44: SEED | D44: CUSTOM&TRIAL | F44: ='5-SEPTEMBER-2026'!Y43+'5-SEPTEMBER-2026'!Z43+'5-SEPTEMBER-2026'!#REF! -> #REF! | G44: =IF(F44<0,"NEGATIVE - CHECK ENTRIES",IF(AND(E44<>"",E44>0,F44<=E44),"REORDER","OK")) -> #REF! | H44: 29-AUGUST-2026
A45: Broccoli TAHOE RZ F3 | B45: 1000 | C45: SEED | D45: COMMERCIAL | F45: ='5-SEPTEMBER-2026'!Y44+'5-SEPTEMBER-2026'!Z44+'5-SEPTEMBER-2026'!#REF! -> #REF! | G45: =IF(F45<0,"NEGATIVE - CHECK ENTRIES",IF(AND(E45<>"",E45>0,F45<=E45),"REORDER","OK")) -> #REF! | H45: 29-AUGUST-2026
A46: Calazina | B46: 100 | C46: SEED | D46: MASIFIO CUSTOM | F46: ='5-SEPTEMBER-2026'!Y45+'5-SEPTEMBER-2026'!Z45+'5-SEPTEMBER-2026'!#REF! -> #REF! | G46: =IF(F46<0,"NEGATIVE - CHECK ENTRIES",IF(AND(E46<>"",E46>0,F46<=E46),"REORDER","OK")) -> #REF! | H46: 29-AUGUST-2026
A47: Cantrell | B47: 100000 | C47: SEED | D47: MASIFIO CUSTOM | F47: ='5-SEPTEMBER-2026'!Y46+'5-SEPTEMBER-2026'!Z46+'5-SEPTEMBER-2026'!#REF! -> #REF! | G47: =IF(F47<0,"NEGATIVE - CHECK ENTRIES",IF(AND(E47<>"",E47>0,F47<=E47),"REORDER","OK")) -> #REF! | H47: 29-AUGUST-2026
A48: Caribbean Gold | B48: 100 | C48: SEED | D48: COMMERCIAL | F48: ='5-SEPTEMBER-2026'!Y47+'5-SEPTEMBER-2026'!Z47+'5-SEPTEMBER-2026'!#REF! -> #REF! | G48: =IF(F48<0,"NEGATIVE - CHECK ENTRIES",IF(AND(E48<>"",E48>0,F48<=E48),"REORDER","OK")) -> #REF! | H48: 29-AUGUST-2026
A49: Caribbean Gold | B49: 100 | C49: SEED | D49: CUSTOM&TRIAL | F49: ='5-SEPTEMBER-2026'!Y48+'5-SEPTEMBER-2026'!Z48+'5-SEPTEMBER-2026'!#REF! -> #REF! | G49: =IF(F49<0,"NEGATIVE - CHECK ENTRIES",IF(AND(E49<>"",E49>0,F49<=E49),"REORDER","OK")) -> #REF! | H49: 29-AUGUST-2026
A50: Caribbean king | B50: 100 | C50: SEED | D50: CUSTOM&TRIAL | F50: ='5-SEPTEMBER-2026'!Y49+'5-SEPTEMBER-2026'!Z49+'5-SEPTEMBER-2026'!#REF! -> #REF! | G50: =IF(F50<0,"NEGATIVE - CHECK ENTRIES",IF(AND(E50<>"",E50>0,F50<=E50),"REORDER","OK")) -> #REF! | H50: 29-AUGUST-2026
A51: Cartegeneous | B51: 1000 | D51: COMMERCIAL | F51: ='5-SEPTEMBER-2026'!Y50+'5-SEPTEMBER-2026'!Z50+'5-SEPTEMBER-2026'!#REF! -> #REF! | G51: =IF(F51<0,"NEGATIVE - CHECK ENTRIES",IF(AND(E51<>"",E51>0,F51<=E51),"REORDER","OK")) -> #REF! | H51: 29-AUGUST-2026
A52: Cauliflower CASPER RZ F1 | B52: 1000 | C52: SEED | D52: COMMERCIAL | F52: ='5-SEPTEMBER-2026'!Y51+'5-SEPTEMBER-2026'!Z51+'5-SEPTEMBER-2026'!#REF! -> #REF! | G52: =IF(F52<0,"NEGATIVE - CHECK ENTRIES",IF(AND(E52<>"",E52>0,F52<=E52),"REORDER","OK")) -> #REF! | H52: 29-AUGUST-2026
A53: Cauliflower CASPER RZ F4 | B53: 1000 | C53: SEED | D53: COMMERCIAL | F53: ='5-SEPTEMBER-2026'!Y52+'5-SEPTEMBER-2026'!Z52+'5-SEPTEMBER-2026'!#REF! -> #REF! | G53: =IF(F53<0,"NEGATIVE - CHECK ENTRIES",IF(AND(E53<>"",E53>0,F53<=E53),"REORDER","OK")) -> #REF! | H53: 29-AUGUST-2026
A54: Cauliflower MONEERA RZ F4 | B54: 1000 | C54: SEED | D54: COMMERCIAL | F54: ='5-SEPTEMBER-2026'!Y53+'5-SEPTEMBER-2026'!Z53+'5-SEPTEMBER-2026'!#REF! -> #REF! | G54: =IF(F54<0,"NEGATIVE - CHECK ENTRIES",IF(AND(E54<>"",E54>0,F54<=E54),"REORDER","OK")) -> #REF! | H54: 29-AUGUST-2026
A55: Chromis | B55: 100 | C55: SEED | D55: MASIFIO CUSTOM | F55: ='5-SEPTEMBER-2026'!Y54+'5-SEPTEMBER-2026'!Z54+'5-SEPTEMBER-2026'!#REF! -> #REF! | G55: =IF(F55<0,"NEGATIVE - CHECK ENTRIES",IF(AND(E55<>"",E55>0,F55<=E55),"REORDER","OK")) -> #REF! | H55: 29-AUGUST-2026
A56: Codex | B56: 1000 | C56: SEED | D56: MASIFIO CUSTOM | F56: ='5-SEPTEMBER-2026'!Y55+'5-SEPTEMBER-2026'!Z55+'5-SEPTEMBER-2026'!#REF! -> #REF! | G56: =IF(F56<0,"NEGATIVE - CHECK ENTRIES",IF(AND(E56<>"",E56>0,F56<=E56),"REORDER","OK")) -> #REF! | H56: 29-AUGUST-2026
A57: concorde | B57: 5000 | C57: SEED | D57: CUSTOM&TRIAL | F57: ='5-SEPTEMBER-2026'!Y56+'5-SEPTEMBER-2026'!Z56+'5-SEPTEMBER-2026'!#REF! -> #REF! | G57: =IF(F57<0,"NEGATIVE - CHECK ENTRIES",IF(AND(E57<>"",E57>0,F57<=E57),"REORDER","OK")) -> #REF! | H57: 29-AUGUST-2026
A58: cook | B58: 1000 | C58: SEED | D58: MASIFIO CUSTOM | F58: ='5-SEPTEMBER-2026'!Y57+'5-SEPTEMBER-2026'!Z57+'5-SEPTEMBER-2026'!#REF! -> #REF! | G58: =IF(F58<0,"NEGATIVE - CHECK ENTRIES",IF(AND(E58<>"",E58>0,F58<=E58),"REORDER","OK")) -> #REF! | H58: 29-AUGUST-2026
A59: Cos lettuce MAXIMUS RZ | B59: 1000 | C59: SEED | D59: COMMERCIAL | F59: ='5-SEPTEMBER-2026'!Y58+'5-SEPTEMBER-2026'!Z58+'5-SEPTEMBER-2026'!#REF! -> #REF! | G59: =IF(F59<0,"NEGATIVE - CHECK ENTRIES",IF(AND(E59<>"",E59>0,F59<=E59),"REORDER","OK")) -> #REF! | H59: 29-AUGUST-2026
A60: Coulthard | B60: 100000 | C60: SEED | D60: MASIFIO CUSTOM | F60: ='5-SEPTEMBER-2026'!Y59+'5-SEPTEMBER-2026'!Z59+'5-SEPTEMBER-2026'!#REF! -> #REF! | G60: =IF(F60<0,"NEGATIVE - CHECK ENTRIES",IF(AND(E60<>"",E60>0,F60<=E60),"REORDER","OK")) -> #REF! | H60: 29-AUGUST-2026
A61: Cucumber LARINO RZ F1 | B61: 100 | C61: SEED | D61: COMMERCIAL | F61: ='5-SEPTEMBER-2026'!Y60+'5-SEPTEMBER-2026'!Z60+'5-SEPTEMBER-2026'!#REF! -> #REF! | G61: =IF(F61<0,"NEGATIVE - CHECK ENTRIES",IF(AND(E61<>"",E61>0,F61<=E61),"REORDER","OK")) -> #REF! | H61: 29-AUGUST-2026
A62: Daywalt | B62: 100000 | C62: SEED | D62: MASIFIO CUSTOM | F62: ='5-SEPTEMBER-2026'!Y61+'5-SEPTEMBER-2026'!Z61+'5-SEPTEMBER-2026'!#REF! -> #REF! | G62: =IF(F62<0,"NEGATIVE - CHECK ENTRIES",IF(AND(E62<>"",E62>0,F62<=E62),"REORDER","OK")) -> #REF! | H62: 29-AUGUST-2026
...

Sheet 26 june
A1: PRODUCT | E1: WAREHOUSE STOCK - OPENING | I1: WEEKLY MOVEMENT (manual entry) | S1: WAREHOUSE STOCK - CLOSING | W1: ALERT | X1: BRANCH DISTRIBUTION (Dar / Dodoma / Iringa / Manyara) | AJ1: NOTES
A2: Product | B2: Pack Size | C2: Category | D2: Type | E2: Opening Arusha | F2: Opening Moro | G2: Opening Dar | H2: Total Qty - Week Start | I2: Sales Arusha | J2: Sales Moro | K2: Sales Dar | L2: Stock Out Arusha | M2: Stock Out Moro | N2: Stock Out Dar | O2: Stock In Arusha | P2: Stock In Moro | Q2: Stock In Dar | R2: Stock In Dodoma | S2: Total Qty - Week End | T2: Closing Arusha | U2: Closing Moro | V2: Closing Dar | W2: Stock Alert | X2: Sent Dar | Y2: Sold Dar | Z2: Not Sold Dar | AA2: Sent Dodoma | AB2: Sold Dodoma | AC2: Not Sold Dodoma | AD2: Sent Iringa | AE2: Sold Iringa | AF2: Not Sold Iringa | AG2: Sent Manyara | AH2: Sold Manyara | AI2: Not Sold Manyara | AJ2: Remarks
A3: 30-WC773 | B3: 1000 | C3: SEED | D3: COMMERCIAL | E3: 0 | F3: 0 | G3: 0 | H3: =E3+F3+G3 -> 0 | I3: 0 | J3: 0 | K3: 0 | L3: 0 | M3: 0 | N3: 0 | O3: 0 | P3: 0 | Q3: 0 | R3: 0 | S3: =H3+O3+P3+Q3+R3-(I3+J3+K3+L3+M3+N3) -> 0 | T3: =E3+O3-I3-L3 -> 0 | U3: =F3+P3-J3-M3 -> 0 | V3: =G3+Q3-K3-N3 -> 0 | W3: =IF(MIN(T3,U3,V3)<0,"NEGATIVE STOCK - CHECK ENTRIES","") | X3: 0 | Y3: 0 | Z3: =X3-Y3 -> 0 | AA3: 0 | AB3: 0 | AC3: =AA3-AB3 -> 0 | AD3: 0 | AE3: 0 | AF3: =AD3-AE3 -> 0 | AG3: 0 | AH3: 0 | AI3: =AG3-AH3 -> 0
A4: Afadja | B4: 500 | C4: SEED | D4: CUSTOM&TRIAL | E4: 0 | F4: 0 | G4: 0 | H4: =E4+F4+G4 -> 0 | I4: 0 | J4: 0 | K4: 0 | L4: 0 | M4: 0 | N4: 0 | O4: 0 | P4: 0 | Q4: 0 | R4: 0 | S4: =H4+O4+P4+Q4+R4-(I4+J4+K4+L4+M4+N4) -> 0 | T4: =E4+O4-I4-L4 -> 0 | U4: =F4+P4-J4-M4 -> 0 | V4: =G4+Q4-K4-N4 -> 0 | W4: =IF(MIN(T4,U4,V4)<0,"NEGATIVE STOCK - CHECK ENTRIES","") | X4: 0 | Y4: 0 | Z4: =X4-Y4 -> 0 | AA4: 0 | AB4: 0 | AC4: =AA4-AB4 -> 0 | AD4: 0 | AE4: 0 | AF4: =AD4-AE4 -> 0 | AG4: 0 | AH4: 0 | AI4: =AG4-AH4 -> 0
A5: African eggplant BENUE F1 | B5: 100 | C5: SEED | D5: COMMERCIAL | E5: 396 | F5: 69 | G5: 190 | H5: =E5+F5+G5 -> 655 | I5: 160 | J5: 0 | K5: 0 | L5: 0 | M5: 0 | N5: 0 | O5: 0 | P5: 0 | Q5: 0 | R5: 0 | S5: =H5+O5+P5+Q5+R5-(I5+J5+K5+L5+M5+N5) -> 495 | T5: =E5+O5-I5-L5 -> 236 | U5: =F5+P5-J5-M5 -> 69 | V5: =G5+Q5-K5-N5 -> 190 | W5: =IF(MIN(T5,U5,V5)<0,"NEGATIVE STOCK - CHECK ENTRIES","") | X5: 0 | Y5: 0 | Z5: =X5-Y5 -> 0 | AA5: 0 | AB5: 0 | AC5: =AA5-AB5 -> 0 | AD5: 0 | AE5: 0 | AF5: =AD5-AE5 -> 0 | AG5: 0 | AH5: 0 | AI5: =AG5-AH5 -> 0
A6: African eggplant KAZINGA RZ F1 | B6: 100 | C6: SEED | D6: COMMERCIAL | E6: 233 | F6: 38 | G6: 52 | H6: =E6+F6+G6 -> 323 | I6: 0 | J6: 0 | K6: 0 | L6: 0 | M6: 0 | N6: 0 | O6: 0 | P6: 0 | Q6: 0 | R6: 0 | S6: =H6+O6+P6+Q6+R6-(I6+J6+K6+L6+M6+N6) -> 323 | T6: =E6+O6-I6-L6 -> 233 | U6: =F6+P6-J6-M6 -> 38 | V6: =G6+Q6-K6-N6 -> 52 | W6: =IF(MIN(T6,U6,V6)<0,"NEGATIVE STOCK - CHECK ENTRIES","") | X6: 0 | Y6: 0 | Z6: =X6-Y6 -> 0 | AA6: 0 | AB6: 0 | AC6: =AA6-AB6 -> 0 | AD6: 0 | AE6: 0 | AF6: =AD6-AE6 -> 0 | AG6: 0 | AH6: 0 | AI6: =AG6-AH6 -> 0
A7: African eggplant KERIO RZ F1 | B7: 100 | C7: SEED | D7: COMMERCIAL | E7: 0 | F7: 20 | G7: 0 | H7: =E7+F7+G7 -> 20 | I7: 0 | J7: 0 | K7: 0 | L7: 0 | M7: 0 | N7: 0 | O7: 0 | P7: 0 | Q7: 0 | R7: 0 | S7: =H7+O7+P7+Q7+R7-(I7+J7+K7+L7+M7+N7) -> 20 | T7: =E7+O7-I7-L7 -> 0 | U7: =F7+P7-J7-M7 -> 20 | V7: =G7+Q7-K7-N7 -> 0 | W7: =IF(MIN(T7,U7,V7)<0,"NEGATIVE STOCK - CHECK ENTRIES","") | X7: 0 | Y7: 0 | Z7: =X7-Y7 -> 0 | AA7: 0 | AB7: 0 | AC7: =AA7-AB7 -> 0 | AD7: 0 | AE7: 0 | AF7: =AD7-AE7 -> 0 | AG7: 0 | AH7: 0 | AI7: =AG7-AH7 -> 0
A8: African eggplant LIMPOPO RZ F3 | B8: 100 | C8: SEED | D8: COMMERCIAL | E8: 0 | F8: 17 | G8: 20 | H8: =E8+F8+G8 -> 37 | I8: 0 | J8: 0 | K8: 0 | L8: 0 | M8: 0 | N8: 0 | O8: 0 | P8: 0 | Q8: 0 | R8: 0 | S8: =H8+O8+P8+Q8+R8-(I8+J8+K8+L8+M8+N8) -> 37 | T8: =E8+O8-I8-L8 -> 0 | U8: =F8+P8-J8-M8 -> 17 | V8: =G8+Q8-K8-N8 -> 20 | W8: =IF(MIN(T8,U8,V8)<0,"NEGATIVE STOCK - CHECK ENTRIES","") | X8: 0 | Y8: 0 | Z8: =X8-Y8 -> 0 | AA8: 0 | AB8: 0 | AC8: =AA8-AB8 -> 0 | AD8: 0 | AE8: 0 | AF8: =AD8-AE8 -> 0 | AG8: 0 | AH8: 0 | AI8: =AG8-AH8 -> 0
A9: African hot pepper AFADJA RZ F7 | B9: 100 | C9: SEED | D9: COMMERCIAL | E9: 0 | F9: 0 | G9: 1 | H9: =E9+F9+G9 -> 1 | I9: 0 | J9: 0 | K9: 0 | L9: 0 | M9: 0 | N9: 0 | O9: 0 | P9: 0 | Q9: 0 | R9: 0 | S9: =H9+O9+P9+Q9+R9-(I9+J9+K9+L9+M9+N9) -> 1 | T9: =E9+O9-I9-L9 -> 0 | U9: =F9+P9-J9-M9 -> 0 | V9: =G9+Q9-K9-N9 -> 1 | W9: =IF(MIN(T9,U9,V9)<0,"NEGATIVE STOCK - CHECK ENTRIES","") | X9: 0 | Y9: 0 | Z9: =X9-Y9 -> 0 | AA9: 0 | AB9: 0 | AC9: =AA9-AB9 -> 0 | AD9: 0 | AE9: 0 | AF9: =AD9-AE9 -> 0 | AG9: 0 | AH9: 0 | AI9: =AG9-AH9 -> 0
A10: African hot pepper AFADJA RZ F7 | B10: 500 | C10: SEED | D10: COMMERCIAL | E10: 0 | F10: 0 | G10: 0 | H10: =E10+F10+G10 -> 0 | I10: 0 | J10: 0 | K10: 0 | L10: 0 | M10: 0 | N10: 0 | O10: 0 | P10: 0 | Q10: 0 | R10: 0 | S10: =H10+O10+P10+Q10+R10-(I10+J10+K10+L10+M10+N10) -> 0 | T10: =E10+O10-I10-L10 -> 0 | U10: =F10+P10-J10-M10 -> 0 | V10: =G10+Q10-K10-N10 -> 0 | W10: =IF(MIN(T10,U10,V10)<0,"NEGATIVE STOCK - CHECK ENTRIES","") | X10: 0 | Y10: 0 | Z10: =X10-Y10 -> 0 | AA10: 0 | AB10: 0 | AC10: =AA10-AB10 -> 0 | AD10: 0 | AE10: 0 | AF10: =AD10-AE10 -> 0 | AG10: 0 | AH10: 0 | AI10: =AG10-AH10 -> 0
A11: African hot pepper LENGAI RZ F2 | B11: 100 | C11: SEED | D11: COMMERCIAL | E11: 329 | F11: 195 | G11: 16 | H11: =E11+F11+G11 -> 540 | I11: 0 | J11: 0 | K11: 0 | L11: 0 | M11: 0 | N11: 0 | O11: 0 | P11: 0 | Q11: 0 | R11: 0 | S11: =H11+O11+P11+Q11+R11-(I11+J11+K11+L11+M11+N11) -> 540 | T11: =E11+O11-I11-L11 -> 329 | U11: =F11+P11-J11-M11 -> 195 | V11: =G11+Q11-K11-N11 -> 16 | W11: =IF(MIN(T11,U11,V11)<0,"NEGATIVE STOCK - CHECK ENTRIES","") | X11: 0 | Y11: 0 | Z11: =X11-Y11 -> 0 | AA11: 0 | AB11: 0 | AC11: =AA11-AB11 -> 0 | AD11: 0 | AE11: 0 | AF11: =AD11-AE11 -> 0 | AG11: 0 | AH11: 0 | AI11: =AG11-AH11 -> 0
A12: African hot pepper LENGAI RZ F3 | B12: 500 | C12: SEED | D12: COMMERCIAL | E12: 8 | F12: 0 | G12: 0 | H12: =E12+F12+G12 -> 8 | I12: 0 | J12: 0 | K12: 0 | L12: 0 | M12: 0 | N12: 0 | O12: 0 | P12: 0 | Q12: 0 | R12: 0 | S12: =H12+O12+P12+Q12+R12-(I12+J12+K12+L12+M12+N12) -> 8 | T12: =E12+O12-I12-L12 -> 8 | U12: =F12+P12-J12-M12 -> 0 | V12: =G12+Q12-K12-N12 -> 0 | W12: =IF(MIN(T12,U12,V12)<0,"NEGATIVE STOCK - CHECK ENTRIES","") | X12: 0 | Y12: 0 | Z12: =X12-Y12 -> 0 | AA12: 0 | AB12: 0 | AC12: =AA12-AB12 -> 0 | AD12: 0 | AE12: 0 | AF12: =AD12-AE12 -> 0 | AG12: 0 | AH12: 0 | AI12: =AG12-AH12 -> 0
A13: African Hot Pepper Loleza RZ | B13: 100 | C13: SEED | D13: COMMERCIAL | E13: 2804 | F13: 302 | G13: 150 | H13: =E13+F13+G13 -> 3256 | I13: 10 | J13: 5 | K13: 0 | L13: 1290 | M13: 0 | N13: 0 | O13: 0 | P13: 0 | Q13: 0 | R13: 0 | S13: =H13+O13+P13+Q13+R13-(I13+J13+K13+L13+M13+N13) -> 1951 | T13: =E13+O13-I13-L13 -> 1504 | U13: =F13+P13-J13-M13 -> 297 | V13: =G13+Q13-K13-N13 -> 150 | W13: =IF(MIN(T13,U13,V13)<0,"NEGATIVE STOCK - CHECK ENTRIES","") | X13: 0 | Y13: 0 | Z13: =X13-Y13 -> 0 | AA13: 0 | AB13: 0 | AC13: =AA13-AB13 -> 0 | AD13: 0 | AE13: 0 | AF13: =AD13-AE13 -> 0 | AG13: 0 | AH13: 0 | AI13: =AG13-AH13 -> 0
A14: African Hot Pepper Loleza RZ | B14: 500 | C14: SEED | D14: COMMERCIAL | E14: 170 | F14: 20 | G14: 15 | H14: =E14+F14+G14 -> 205 | I14: 0 | J14: 0 | K14: 0 | L14: 0 | M14: 0 | N14: 0 | O14: 0 | P14: 0 | Q14: 0 | R14: 0 | S14: =H14+O14+P14+Q14+R14-(I14+J14+K14+L14+M14+N14) -> 205 | T14: =E14+O14-I14-L14 -> 170 | U14: =F14+P14-J14-M14 -> 20 | V14: =G14+Q14-K14-N14 -> 15 | W14: =IF(MIN(T14,U14,V14)<0,"NEGATIVE STOCK - CHECK ENTRIES","") | X14: 0 | Y14: 0 | Z14: =X14-Y14 -> 0 | AA14: 0 | AB14: 0 | AC14: =AA14-AB14 -> 0 | AD14: 0 | AE14: 0 | AF14: =AD14-AE14 -> 0 | AG14: 0 | AH14: 0 | AI14: =AG14-AH14 -> 0
... A48: Caribbean king | B48: 100 | C48: SEED | D48: CUSTOM&TRIAL | E48: 0 | F48: 0 | G48: 0 | H48: =E48+F48+G48 -> 0 | I48: 0 | J48: 0 | K48: 0 | L48: 0 | M48: 0 | N48: 0 | O48: 0 | P48: 0 | Q48: 0 | R48: 0 | S48: =H48+O48+P48+Q48+R48-(I48+J48+K48+L48+M48+N48) -> 0 | T48: =E48+O48-I48-L48 -> 0 | U48: =F48+P48-J48-M48 -> 0 | V48: =G48+Q48-K48-N48 -> 0 | W48: =IF(MIN(T48,U48,V48)<0,"NEGATIVE STOCK - CHECK ENTRIES","") | X48: 0 | Y48: 0 | Z48: =X48-Y48 -> 0 | AA48: 0 | AB48: 0 | AC48: =AA48-AB48 -> 0 | AD48: 0 | AE48: 0 | AF48: =AD48-AE48 -> 0 | AG48: 0 | AH48: 0 | AI48: =AG48-AH48 -> 0
A49: Cartegeneous | B49: 1000 | D49: COMMERCIAL | E49: 0 | F49: 0 | G49: 0 | H49: =E49+F49+G49 -> 0 | I49: 0 | J49: 0 | K49: 0 | L49: 0 | M49: 0 | N49: 0 | O49: 0 | P49: 0 | Q49: 0 | R49: 0 | S49: =H49+O49+P49+Q49+R49-(I49+J49+K49+L49+M49+N49) -> 0 | T49: =E49+O49-I49-L49 -> 0 | U49: =F49+P49-J49-M49 -> 0 | V49: =G49+Q49-K49-N49 -> 0 | W49: =IF(MIN(T49,U49,V49)<0,"NEGATIVE STOCK - CHECK ENTRIES","") | X49: 0 | Y49: 0 | Z49: =X49-Y49 -> 0 | AA49: 0 | AB49: 0 | AC49: =AA49-AB49 -> 0 | AD49: 0 | AE49: 0 | AF49: =AD49-AE49 -> 0 | AG49: 0 | AH49: 0 | AI49: =AG49-AH49 -> 0
A50: Cauliflower CASPER RZ F1 | B50: 1000 | C50: SEED | D50: COMMERCIAL | E50: 0 | F50: 0 | G50: 0 | H50: =E50+F50+G50 -> 0 | I50: 0 | J50: 0 | K50: 0 | L50: 0 | M50: 0 | N50: 0 | O50: 0 | P50: 0 | Q50: 0 | R50: 0 | S50: =H50+O50+P50+Q50+R50-(I50+J50+K50+L50+M50+N50) -> 0 | T50: =E50+O50-I50-L50 -> 0 | U50: =F50+P50-J50-M50 -> 0 | V50: =G50+Q50-K50-N50 -> 0 | W50: =IF(MIN(T50,U50,V50)<0,"NEGATIVE STOCK - CHECK ENTRIES","") | X50: 0 | Y50: 0 | Z50: =X50-Y50 -> 0 | AA50: 0 | AB50: 0 | AC50: =AA50-AB50 -> 0 | AD50: 0 | AE50: 0 | AF50: =AD50-AE50 -> 0 | AG50: 0 | AH50: 0 | AI50: =AG50-AH50 -> 0
A51: Cauliflower CASPER RZ F4 | B51: 1000 | C51: SEED | D51: COMMERCIAL | E51: 7 | F51: 24 | G51: 0 | H51: =E51+F51+G51 -> 31 | I51: 6 | J51: 0 | K51: 0 | L51: 5 | M51: 7 | N51: 0 | O51: 7 | P51: 0 | Q51: 0 | R51: 0 | S51: =H51+O51+P51+Q51+R51-(I51+J51+K51+L51+M51+N51) -> 20 | T51: =E51+O51-I51-L51 -> 3 | U51: =F51+P51-J51-M51 -> 17 | V51: =G51+Q51-K51-N51 -> 0 | W51: =IF(MIN(T51,U51,V51)<0,"NEGATIVE STOCK - CHECK ENTRIES","") | X51: 0 | Y51: 0 | Z51: =X51-Y51 -> 0 | AA51: 0 | AB51: 0 | AC51: =AA51-AB51 -> 0 | AD51: 0 | AE51: 0 | AF51: =AD51-AE51 -> 0 | AG51: 0 | AH51: 0 | AI51: =AG51-AH51 -> 0
A52: Cauliflower MONEERA RZ F4 | B52: 1000 | C52: SEED | D52: COMMERCIAL | E52: 5 | F52: 1 | G52: 2 | H52: =E52+F52+G52 -> 8 | I52: 0 | J52: 0 | K52: 0 | L52: 0 | M52: 0 | N52: 0 | O52: 0 | P52: 0 | Q52: 0 | R52: 0 | S52: =H52+O52+P52+Q52+R52-(I52+J52+K52+L52+M52+N52) -> 8 | T52: =E52+O52-I52-L52 -> 5 | U52: =F52+P52-J52-M52 -> 1 | V52: =G52+Q52-K52-N52 -> 2 | W52: =IF(MIN(T52,U52,V52)<0,"NEGATIVE STOCK - CHECK ENTRIES","") | X52: 0 | Y52: 0 | Z52: =X52-Y52 -> 0 | AA52: 0 | AB52: 0 | AC52: =AA52-AB52 -> 0 | AD52: 0 | AE52: 0 | AF52: =AD52-AE52 -> 0 | AG52: 0 | AH52: 0 | AI52: =AG52-AH52 -> 0
A53: Chromis | B53: 100 | C53: SEED | D53: MASIFIO CUSTOM | E53: 0 | F53: 0 | G53: 0 | H53: =E53+F53+G53 -> 0 | I53: 0 | J53: 0 | K53: 0 | L53: 0 | M53: 0 | N53: 0 | O53: 0 | P53: 0 | Q53: 0 | R53: 0 | S53: =H53+O53+P53+Q53+R53-(I53+J53+K53+L53+M53+N53) -> 0 | T53: =E53+O53-I53-L53 -> 0 | U53: =F53+P53-J53-M53 -> 0 | V53: =G53+Q53-K53-N53 -> 0 | W53: =IF(MIN(T53,U53,V53)<0,"NEGATIVE STOCK - CHECK ENTRIES","") | X53: 0 | Y53: 0 | Z53: =X53-Y53 -> 0 | AA53: 0 | AB53: 0 | AC53: =AA53-AB53 -> 0 | AD53: 0 | AE53: 0 | AF53: =AD53-AE53 -> 0 | AG53: 0 | AH53: 0 | AI53: =AG53-AH53 -> 0
A54: Codex | B54: 1000 | C54: SEED | D54: MASIFIO CUSTOM | E54: 0 | F54: 0 | G54: 0 | H54: =E54+F54+G54 -> 0 | I54: 0 | J54: 0 | K54: 0 | L54: 0 | M54: 0 | N54: 0 | O54: 0 | P54: 0 | Q54: 0 | R54: 0 | S54: =H54+O54+P54+Q54+R54-(I54+J54+K54+L54+M54+N54) -> 0 | T54: =E54+O54-I54-L54 -> 0 | U54: =F54+P54-J54-M54 -> 0 | V54: =G54+Q54-K54-N54 -> 0 | W54: =IF(MIN(T54,U54,V54)<0,"NEGATIVE STOCK - CHECK ENTRIES","") | X54: 0 | Y54: 0 | Z54: =X54-Y54 -> 0 | AA54: 0 | AB54: 0 | AC54: =AA54-AB54 -> 0 | AD54: 0 | AE54: 0 | AF54: =AD54-AE54 -> 0 | AG54: 0 | AH54: 0 | AI54: =AG54-AH54 -> 0
A55: concorde | B55: 5000 | C55: SEED | D55: CUSTOM&TRIAL | E55: 0 | F55: 0 | G55: 0 | H55: =E55+F55+G55 -> 0 | I55: 0 | J55: 0 | K55: 0 | L55: 0 | M55: 0 | N55: 0 | O55: 0 | P55: 0 | Q55: 0 | R55: 0 | S55: =H55+O55+P55+Q55+R55-(I55+J55+K55+L55+M55+N55) -> 0 | T55: =E55+O55-I55-L55 -> 0 | U55: =F55+P55-J55-M55 -> 0 | V55: =G55+Q55-K55-N55 -> 0 | W55: =IF(MIN(T55,U55,V55)<0,"NEGATIVE STOCK - CHECK ENTRIES","") | X55: 0 | Y55: 0 | Z55: =X55-Y55 -> 0 | AA55: 0 | AB55: 0 | AC55: =AA55-AB55 -> 0 | AD55: 0 | AE55: 0 | AF55: =AD55-AE55 -> 0 | AG55: 0 | AH55: 0 | AI55: =AG55-AH55 -> 0
A56: cook | B56: 1000 | C56: SEED | D56: MASIFIO CUSTOM | E56: 0 | F56: 0 | G56: 0 | H56: =E56+F56+G56 -> 0 | I56: 0 | J56: 0 | K56: 0 | L56: 0 | M56: 0 | N56: 0 | O56: 0 | P56: 0 | Q56: 0 | R56: 0 | S56: =H56+O56+P56+Q56+R56-(I56+J56+K56+L56+M56+N56) -> 0 | T56: =E56+O56-I56-L56 -> 0 | U56: =F56+P56-J56-M56 -> 0 | V56: =G56+Q56-K56-N56 -> 0 | W56: =IF(MIN(T56,U56,V56)<0,"NEGATIVE STOCK - CHECK ENTRIES","") | X56: 0 | Y56: 0 | Z56: =X56-Y56 -> 0 | AA56: 0 | AB56: 0 | AC56: =AA56-AB56 -> 0 | AD56: 0 | AE56: 0 | AF56: =AD56-AE56 -> 0 | AG56: 0 | AH56: 0 | AI56: =AG56-AH56 -> 0
A57: Cos lettuce MAXIMUS RZ | B57: 1000 | C57: SEED | D57: COMMERCIAL | E57: 0 | F57: 2 | G57: 0 | H57: =E57+F57+G57 -> 2 | I57: 0 | J57: 0 | K57: 0 | L57: 0 | M57: 0 | N57: 0 | O57: 0 | P57: 0 | Q57: 0 | R57: 0 | S57: =H57+O57+P57+Q57+R57-(I57+J57+K57+L57+M57+N57) -> 2 | T57: =E57+O57-I57-L57 -> 0 | U57: =F57+P57-J57-M57 -> 2 | V57: =G57+Q57-K57-N57 -> 0 | W57: =IF(MIN(T57,U57,V57)<0,"NEGATIVE STOCK - CHECK ENTRIES","") | X57: 0 | Y57: 0 | Z57: =X57-Y57 -> 0 | AA57: 0 | AB57: 0 | AC57: =AA57-AB57 -> 0 | AD57: 0 | AE57: 0 | AF57: =AD57-AE57 -> 0 | AG57: 0 | AH57: 0 | AI57: =AG57-AH57 -> 0
A58: Coulthard | B58: 100000 | C58: SEED | D58: MASIFIO CUSTOM | E58: 0 | F58: 0 | G58: 0 | H58: =E58+F58+G58 -> 0 | I58: 0 | J58: 0 | K58: 0 | L58: 0 | M58: 0 | N58: 0 | O58: 0 | P58: 0 | Q58: 0 | R58: 0 | S58: =H58+O58+P58+Q58+R58-(I58+J58+K58+L58+M58+N58) -> 0 | T58: =E58+O58-I58-L58 -> 0 | U58: =F58+P58-J58-M58 -> 0 | V58: =G58+Q58-K58-N58 -> 0 | W58: =IF(MIN(T58,U58,V58)<0,"NEGATIVE STOCK - CHECK ENTRIES","") | X58: 0 | Y58: 0 | Z58: =X58-Y58 -> 0 | AA58: 0 | AB58: 0 | AC58: =AA58-AB58 -> 0 | AD58: 0 | AE58: 0 | AF58: =AD58-AE58 -> 0 | AG58: 0 | AH58: 0 | AI58: =AG58-AH58 -> 0
A59: Cucumber LARINO RZ F1 | B59: 100 | C59: SEED | D59: COMMERCIAL | E59: 0 | F59: 0 | G59: 6 | H59: =E59+F59+G59 -> 6 | I59: 0 | J59: 0 | K59: 0 | L59: 0 | M59: 0 | N59: 0 | O59: 0 | P59: 0 | Q59: 0 | R59: 0 | S59: =H59+O59+P59+Q59+R59-(I59+J59+K59+L59+M59+N59) -> 6 | T59: =E59+O59-I59-L59 -> 0 | U59: =F59+P59-J59-M59 -> 0 | V59: =G59+Q59-K59-N59 -> 6 | W59: =IF(MIN(T59,U59,V59)<0,"NEGATIVE STOCK - CHECK ENTRIES","") | X59: 0 | Y59: 0 | Z59: =X59-Y59 -> 0 | AA59: 0 | AB59: 0 | AC59: =AA59-AB59 -> 0 | AD59: 0 | AE59: 0 | AF59: =AD59-AE59 -> 0 | AG59: 0 | AH59: 0 | AI59: =AG59-AH59 -> 0
A60: Daywalt | B60: 100000 | C60: SEED | D60: MASIFIO CUSTOM | E60: 0 | F60: 0 | G60: 0 | H60: =E60+F60+G60 -> 0 | I60: 0 | J60: 0 | K60: 0 | L60: 0 | M60: 0 | N60: 0 | O60: 0 | P60: 0 | Q60: 0 | R60: 0 | S60: =H60+O60+P60+Q60+R60-(I60+J60+K60+L60+M60+N60) -> 0 | T60: =E60+O60-I60-L60 -> 0 | U60: =F60+P60-J60-M60 -> 0 | V60: =G60+Q60-K60-N60 -> 0 | W60: =IF(MIN(T60,U60,V60)<0,"NEGATIVE STOCK - CHECK ENTRIES","") | X60: 0 | Y60: 0 | Z60: =X60-Y60 -> 0 | AA60: 0 | AB60: 0 | AC60: =AA60-AB60 -> 0 | AD60: 0 | AE60: 0 | AF60: =AD60-AE60 -> 0 | AG60: 0 | AH60: 0 | AI60: =AG60-AH60 -> 0
A61: Diapson | B61: 100 | C61: SEED | D61: MASIFIO CUSTOM | E61: 0 | F61: 0 | G61: 0 | H61: =E61+F61+G61 -> 0 | I61: 0 | J61: 0 | K61: 0 | L61: 0 | M61: 0 | N61: 0 | O61: 0 | P61: 0 | Q61: 0 | R61: 0 | S61: =H61+O61+P61+Q61+R61-(I61+J61+K61+L61+M61+N61) -> 0 | T61: =E61+O61-I61-L61 -> 0 | U61: =F61+P61-J61-M61 -> 0 | V61: =G61+Q61-K61-N61 -> 0 | W61: =IF(MIN(T61,U61,V61)<0,"NEGATIVE STOCK - CHECK ENTRIES","") | X61: 0 | Y61: 0 | Z61: =X61-Y61 -> 0 | AA61: 0 | AB61: 0 | AC61: =AA61-AB61 -> 0 | AD61: 0 | AE61: 0 | AF61: =AD61-AE61 -> 0 | AG61: 0 | AH61: 0 | AI61: =AG61-AH61 -> 0
... A74: grecale | B74: 1000 | C74: SEED | D74: MASIFIO CUSTOM | E74: 0 | F74: 0 | G74: 0 | H74: =E74+F74+G74 -> 0 | I74: 0 | J74: 0 | K74: 0 | L74: 0 | M74: 0 | N74: 0 | O74: 0 | P74: 0 | Q74: 0 | R74: 0 | S74: =H74+O74+P74+Q74+R74-(I74+J74+K74+L74+M74+N74) -> 0 | T74: =E74+O74-I74-L74 -> 0 | U74: =F74+P74-J74-M74 -> 0 | V74: =G74+Q74-K74-N74 -> 0 | W74: =IF(MIN(T74,U74,V74)<0,"NEGATIVE STOCK - CHECK ENTRIES","") | X74: 0 | Y74: 0 | Z74: =X74-Y74 -> 0 | AA74: 0 | AB74: 0 | AC74: =AA74-AB74 -> 0 | AD74: 0 | AE74: 0 | AF74: =AD74-AE74 -> 0 | AG74: 0 | AH74: 0 | AI74: =AG74-AH74 -> 0
A75: GREEN HOUSE | B75: NOT COMPLETE | C75: GREEN HOUSE | D75: COMMERCIAL | E75: 0 | F75: 0 | G75: 0 | H75: =E75+F75+G75 -> 0 | I75: 0 | J75: 0 | K75: 0 | L75: 0 | M75: 0 | N75: 0 | O75: 0 | P75: 0 | Q75: 0 | R75: 0 | S75: =H75+O75+P75+Q75+R75-(I75+J75+K75+L75+M75+N75) -> 0 | T75: =E75+O75-I75-L75 -> 0 | U75: =F75+P75-J75-M75 -> 0 | V75: =G75+Q75-K75-N75 -> 0 | W75: =IF(MIN(T75,U75,V75)<0,"NEGATIVE STOCK - CHECK ENTRIES","") | X75: 0 | Y75: 0 | Z75: =X75-Y75 -> 0 | AA75: 0 | AB75: 0 | AC75: =AA75-AB75 -> 0 | AD75: 0 | AE75: 0 | AF75: =AD75-AE75 -> 0 | AG75: 0 | AH75: 0 | AI75: =AG75-AH75 -> 0
A76: Hazleton | B76: 1000 | C76: SEED | D76: MASIFIO CUSTOM | E76: 0 | F76: 0 | G76: 0 | H76: =E76+F76+G76 -> 0 | I76: 0 | J76: 0 | K76: 0 | L76: 0 | M76: 0 | N76: 0 | O76: 0 | P76: 0 | Q76: 0 | R76: 0 | S76: =H76+O76+P76+Q76+R76-(I76+J76+K76+L76+M76+N76) -> 0 | T76: =E76+O76-I76-L76 -> 0 | U76: =F76+P76-J76-M76 -> 0 | V76: =G76+Q76-K76-N76 -> 0 | W76: =IF(MIN(T76,U76,V76)<0,"NEGATIVE STOCK - CHECK ENTRIES","") | X76: 0 | Y76: 0 | Z76: =X76-Y76 -> 0 | AA76: 0 | AB76: 0 | AC76: =AA76-AB76 -> 0 | AD76: 0 | AE76: 0 | AF76: =AD76-AE76 -> 0 | AG76: 0 | AH76: 0 | AI76: =AG76-AH76 -> 0
A77: Hilbert | B77: 1000 | C77: SEED | D77: MASIFIO CUSTOM | E77: 0 | F77: 0 | G77: 0 | H77: =E77+F77+G77 -> 0 | I77: 0 | J77: 0 | K77: 0 | L77: 0 | M77: 0 | N77: 0 | O77: 0 | P77: 0 | Q77: 0 | R77: 0 | S77: =H77+O77+P77+Q77+R77-(I77+J77+K77+L77+M77+N77) -> 0 | T77: =E77+O77-I77-L77 -> 0 | U77: =F77+P77-J77-M77 -> 0 | V77: =G77+Q77-K77-N77 -> 0 | W77: =IF(MIN(T77,U77,V77)<0,"NEGATIVE STOCK - CHECK ENTRIES","") | X77: 0 | Y77: 0 | Z77: =X77-Y77 -> 0 | AA77: 0 | AB77: 0 | AC77: =AA77-AB77 -> 0 | AD77: 0 | AE77: 0 | AF77: =AD77-AE77 -> 0 | AG77: 0 | AH77: 0 | AI77: =AG77-AH77 -> 0
A78: Horiver Blue | B78: 0 | C78: IPM | D78: COMMERCIAL | E78: 117 | F78: 6 | G78: 16 | H78: =E78+F78+G78 -> 139 | I78: 0 | J78: 0 | K78: 12 | L78: 10 | M78: 0 | N78: 0 | O78: 0 | P78: 0 | Q78: 0 | R78: 0 | S78: =H78+O78+P78+Q78+R78-(I78+J78+K78+L78+M78+N78) -> 117 | T78: =E78+O78-I78-L78 -> 107 | U78: =F78+P78-J78-M78 -> 6 | V78: =G78+Q78-K78-N78 -> 4 | W78: =IF(MIN(T78,U78,V78)<0,"NEGATIVE STOCK - CHECK ENTRIES","") | X78: 0 | Y78: 0 | Z78: =X78-Y78 -> 0 | AA78: 0 | AB78: 0 | AC78: =AA78-AB78 -> 0 | AD78: 0 | AE78: 0 | AF78: =AD78-AE78 -> 0 | AG78: 0 | AH78: 0 | AI78: =AG78-AH78 -> 0
A79: Horiver Yellow | B79: 0 | C79: IPM | D79: COMMERCIAL | E79: 106 | F79: 4 | G79: 11 | H79: =E79+F79+G79 -> 121 | I79: 0 | J79: 0 | K79: 2 | L79: 10 | M79: 0 | N79: 0 | O79: 0 | P79: 0 | Q79: 0 | R79: 0 | S79: =H79+O79+P79+Q79+R79-(I79+J79+K79+L79+M79+N79) -> 109 | T79: =E79+O79-I79-L79 -> 96 | U79: =F79+P79-J79-M79 -> 4 | V79: =G79+Q79-K79-N79 -> 9 | W79: =IF(MIN(T79,U79,V79)<0,"NEGATIVE STOCK - CHECK ENTRIES","") | X79: 0 | Y79: 0 | Z79: =X79-Y79 -> 0 | AA79: 0 | AB79: 0 | AC79: =AA79-AB79 -> 0 | AD79: 0 | AE79: 0 | AF79: =AD79-AE79 -> 0 | AG79: 0 | AH79: 0 | AI79: =AG79-AH79 -> 0
A80: Hot pepper HABIB RZ F1 | B80: 100 | C80: SEED | D80: COMMERCIAL | E80: 48 | F80: 135 | G80: 105 | H80: =E80+F80+G80 -> 288 | I80: 0 | J80: 0 | K80: 1 | L80: 0 | M80: 0 | N80: 0 | O80: 0 | P80: 0 | Q80: 0 | R80: 0 | S80: =H80+O80+P80+Q80+R80-(I80+J80+K80+L80+M80+N80) -> 287 | T80: =E80+O80-I80-L80 -> 48 | U80: =F80+P80-J80-M80 -> 135 | V80: =G80+Q80-K80-N80 -> 104 | W80: =IF(MIN(T80,U80,V80)<0,"NEGATIVE STOCK - CHECK ENTRIES","") | X80: 0 | Y80: 0 | Z80: =X80-Y80 -> 0 | AA80: 0 | AB80: 0 | AC80: =AA80-AB80 -> 0 | AD80: 0 | AE80: 0 | AF80: =AD80-AE80 -> 0 | AG80: 0 | AH80: 0 | AI80: =AG80-AH80 -> 0
A81: Hot pepper MEXTIZO RZ F3 | B81: 500 | C81: SEED | D81: COMMERCIAL | E81: 7 | F81: 0 | G81: 0 | H81: =E81+F81+G81 -> 7 | I81: 0 | J81: 0 | K81: 0 | L81: 0 | M81: 0 | N81: 0 | O81: 0 | P81: 0 | Q81: 0 | R81: 0 | S81: =H81+O81+P81+Q81+R81-(I81+J81+K81+L81+M81+N81) -> 7 | T81: =E81+O81-I81-L81 -> 7 | U81: =F81+P81-J81-M81 -> 0 | V81: =G81+Q81-K81-N81 -> 0 | W81: =IF(MIN(T81,U81,V81)<0,"NEGATIVE STOCK - CHECK ENTRIES","") | X81: 0 | Y81: 0 | Z81: =X81-Y81 -> 0 | AA81: 0 | AB81: 0 | AC81: =AA81-AB81 -> 0 | AD81: 0 | AE81: 0 | AF81: =AD81-AE81 -> 0 | AG81: 0 | AH81: 0 | AI81: =AG81-AH81 -> 0
A82: Hot pepper MEXTIZO RZ F4 | B82: 100 | C82: SEED | D82: COMMERCIAL | E82: 77 | F82: 277 | G82: 37 | H82: =E82+F82+G82 -> 391 | I82: 0 | J82: 0 | K82: 2 | L82: 0 | M82: 0 | N82: 0 | O82: 0 | P82: 0 | Q82: 0 | R82: 0 | S82: =H82+O82+P82+Q82+R82-(I82+J82+K82+L82+M82+N82) -> 389 | T82: =E82+O82-I82-L82 -> 77 | U82: =F82+P82-J82-M82 -> 277 | V82: =G82+Q82-K82-N82 -> 35 | W82: =IF(MIN(T82,U82,V82)<0,"NEGATIVE STOCK - CHECK ENTRIES","") | X82: 0 | Y82: 0 | Z82: =X82-Y82 -> 0 | AA82: 0 | AB82: 0 | AC82: =AA82-AB82 -> 0 | AD82: 0 | AE82: 0 | AF82: =AD82-AE82 -> 0 | AG82: 0 | AH82: 0 | AI82: =AG82-AH82 -> 0
A83: Iceberg lettuce Bruma RZ | B83: 1000 | C83: SEED | D83: COMMERCIAL | E83: 0 | F83: 0 | G83: 0 | H83: =E83+F83+G83 -> 0 | I83: 3 | J83: 0 | K83: 0 | L83: 0 | M83: 0 | N83: 0 | O83: 0 | P83: 0 | Q83: 0 | R83: 0 | S83: =H83+O83+P83+Q83+R83-(I83+J83+K83+L83+M83+N83) -> -3 | T83: =E83+O83-I83-L83 -> -3 | U83: =F83+P83-J83-M83 -> 0 | V83: =G83+Q83-K83-N83 -> 0 | W83: =IF(MIN(T83,U83,V83)<0,"NEGATIVE STOCK - CHECK ENTRIES","") -> NEGATIVE STOCK - CHECK ENTRIES | X83: 0 | Y83: 0 | Z83: =X83-Y83 -> 0 | AA83: 0 | AB83: 0 | AC83: =AA83-AB83 -> 0 | AD83: 0 | AE83: 0 | AF83: =AD83-AE83 -> 0 | AG83: 0 | AH83: 0 | AI83: =AG83-AH83 -> 0
A84: Ilanga | B84: 100 | C84: SEED | D84: CUSTOM&TRIAL | E84: 0 | F84: 0 | G84: 0 | H84: =E84+F84+G84 -> 0 | I84: 0 | J84: 0 | K84: 0 | L84: 0 | M84: 0 | N84: 0 | O84: 0 | P84: 0 | Q84: 0 | R84: 0 | S84: =H84+O84+P84+Q84+R84-(I84+J84+K84+L84+M84+N84) -> 0 | T84: =E84+O84-I84-L84 -> 0 | U84: =F84+P84-J84-M84 -> 0 | V84: =G84+Q84-K84-N84 -> 0 | W84: =IF(MIN(T84,U84,V84)<0,"NEGATIVE STOCK - CHECK ENTRIES","") | X84: 0 | Y84: 0 | Z84: =X84-Y84 -> 0 | AA84: 0 | AB84: 0 | AC84: =AA84-AB84 -> 0 | AD84: 0 | AE84: 0 | AF84: =AD84-AE84 -> 0 | AG84: 0 | AH84: 0 | AI84: =AG84-AH84 -> 0
A85: Jarrah | B85: 100 | C85: SEED | D85: CUSTOM&TRIAL | E85: 0 | F85: 0 | G85: 0 | H85: =E85+F85+G85 -> 0 | I85: 0 | J85: 0 | K85: 0 | L85: 0 | M85: 0 | N85: 0 | O85: 0 | P85: 0 | Q85: 0 | R85: 0 | S85: =H85+O85+P85+Q85+R85-(I85+J85+K85+L85+M85+N85) -> 0 | T85: =E85+O85-I85-L85 -> 0 | U85: =F85+P85-J85-M85 -> 0 | V85: =G85+Q85-K85-N85 -> 0 | W85: =IF(MIN(T85,U85,V85)<0,"NEGATIVE STOCK - CHECK ENTRIES","") | X85: 0 | Y85: 0 | Z85: =X85-Y85 -> 0 | AA85: 0 | AB85: 0 | AC85: =AA85-AB85 -> 0 | AD85: 0 | AE85: 0 | AF85: =AD85-AE85 -> 0 | AG85: 0 | AH85: 0 | AI85: =AG85-AH85 -> 0
...

Sheet 3-july2026
A1: PRODUCT | E1: WAREHOUSE STOCK - OPENING | I1: WEEKLY MOVEMENT (manual entry) | S1: WAREHOUSE STOCK - CLOSING | W1: ALERT | X1: BRANCH DISTRIBUTION (Dar / Dodoma / Iringa / Manyara) | AJ1: NOTES
A2: Product | B2: Pack Size | C2: Category | D2: Type | E2: Opening Arusha | F2: Opening Moro | G2: Opening Dar | H2: Total Qty - Week Start | I2: Sales Arusha | J2: Sales Moro | K2: Sales Dar | L2: Stock Out Arusha | M2: Stock Out Moro | N2: Stock Out Dar | O2: Stock In Arusha | P2: Stock In Moro | Q2: Stock In Dar | R2: Stock In Dodoma | S2: Total Qty - Week End | T2: Closing Arusha | U2: Closing Moro | V2: Closing Dar | W2: Stock Alert | X2: Sent Dar | Y2: Sold Dar | Z2: Not Sold Dar | AA2: Sent Dodoma | AB2: Sold Dodoma | AC2: Not Sold Dodoma | AD2: Sent Iringa | AE2: Sold Iringa | AF2: Not Sold Iringa | AG2: Sent Manyara | AH2: Sold Manyara | AI2: Not Sold Manyara | AJ2: Remarks
A3: 30-WC773 | B3: 1000 | C3: SEED | D3: COMMERCIAL | E3: 0 | F3: 0 | G3: 0 | H3: =E3+F3+G3 -> 0 | I3: 0 | J3: 0 | K3: 0 | L3: 0 | M3: 0 | N3: 0 | O3: 0 | P3: 0 | Q3: 0 | R3: 0 | S3: =H3+O3+P3+Q3+R3-(I3+J3+K3+L3+M3+N3) -> 0 | T3: =E3+O3-I3-L3 -> 0 | U3: =F3+P3-J3-M3 -> 0 | V3: =G3+Q3-K3-N3 -> 0 | W3: =IF(MIN(T3,U3,V3)<0,"NEGATIVE STOCK - CHECK ENTRIES","") | X3: 0 | Y3: 0 | Z3: =X3-Y3 -> 0 | AA3: 0 | AB3: 0 | AC3: =AA3-AB3 -> 0 | AD3: 0 | AE3: 0 | AF3: =AD3-AE3 -> 0 | AG3: 0 | AH3: 0 | AI3: =AG3-AH3 -> 0
A4: Afadja | B4: 500 | C4: SEED | D4: CUSTOM&TRIAL | E4: 0 | F4: 0 | G4: 0 | H4: =E4+F4+G4 -> 0 | I4: 0 | J4: 0 | K4: 0 | L4: 0 | M4: 0 | N4: 0 | O4: 0 | P4: 0 | Q4: 0 | R4: 0 | S4: =H4+O4+P4+Q4+R4-(I4+J4+K4+L4+M4+N4) -> 0 | T4: =E4+O4-I4-L4 -> 0 | U4: =F4+P4-J4-M4 -> 0 | V4: =G4+Q4-K4-N4 -> 0 | W4: =IF(MIN(T4,U4,V4)<0,"NEGATIVE STOCK - CHECK ENTRIES","") | X4: 0 | Y4: 0 | Z4: =X4-Y4 -> 0 | AA4: 0 | AB4: 0 | AC4: =AA4-AB4 -> 0 | AD4: 0 | AE4: 0 | AF4: =AD4-AE4 -> 0 | AG4: 0 | AH4: 0 | AI4: =AG4-AH4 -> 0
A5: African eggplant BENUE F1 | B5: 100 | C5: SEED | D5: COMMERCIAL | E5: ='26 june'!T5 -> 236 | F5: ='26 june'!U5 -> 69 | G5: ='26 june'!V5 -> 190 | H5: =E5+F5+G5 -> 495 | I5: 0 | J5: 0 | K5: 4 | L5: 0 | M5: 0 | N5: 0 | O5: 0 | P5: 0 | Q5: 0 | R5: 0 | S5: =H5+O5+P5+Q5+R5-(I5+J5+K5+L5+M5+N5) -> 491 | T5: =E5+O5-I5-L5 -> 236 | U5: =F5+P5-J5-M5 -> 69 | V5: =G5+Q5-K5-N5 -> 186 | W5: =IF(MIN(T5,U5,V5)<0,"NEGATIVE STOCK - CHECK ENTRIES","") | X5: 0 | Y5: 0 | Z5: =X5-Y5 -> 0 | AA5: 0 | AB5: 0 | AC5: =AA5-AB5 -> 0 | AD5: 0 | AE5: 0 | AF5: =AD5-AE5 -> 0 | AG5: 0 | AH5: 0 | AI5: =AG5-AH5 -> 0
A6: African eggplant KAZINGA RZ F1 | B6: 100 | C6: SEED | D6: COMMERCIAL | E6: ='26 june'!T6 -> 233 | F6: ='26 june'!U6 -> 38 | G6: ='26 june'!V6 -> 52 | H6: =E6+F6+G6 -> 323 | I6: 0 | J6: 0 | K6: 3 | L6: 0 | M6: 0 | N6: 0 | O6: 0 | P6: 0 | Q6: 0 | R6: 0 | S6: =H6+O6+P6+Q6+R6-(I6+J6+K6+L6+M6+N6) -> 320 | T6: =E6+O6-I6-L6 -> 233 | U6: =F6+P6-J6-M6 -> 38 | V6: =G6+Q6-K6-N6 -> 49 | W6: =IF(MIN(T6,U6,V6)<0,"NEGATIVE STOCK - CHECK ENTRIES","") | X6: 0 | Y6: 0 | Z6: =X6-Y6 -> 0 | AA6: 0 | AB6: 0 | AC6: =AA6-AB6 -> 0 | AD6: 0 | AE6: 0 | AF6: =AD6-AE6 -> 0 | AG6: 0 | AH6: 0 | AI6: =AG6-AH6 -> 0
A7: African eggplant KERIO RZ F1 | B7: 100 | C7: SEED | D7: COMMERCIAL | E7: ='26 june'!T7 -> 0 | F7: ='26 june'!U7 -> 20 | G7: ='26 june'!V7 -> 0 | H7: =E7+F7+G7 -> 20 | I7: 0 | J7: 0 | K7: 0 | L7: 0 | M7: 0 | N7: 0 | O7: 0 | P7: 0 | Q7: 0 | R7: 0 | S7: =H7+O7+P7+Q7+R7-(I7+J7+K7+L7+M7+N7) -> 20 | T7: =E7+O7-I7-L7 -> 0 | U7: =F7+P7-J7-M7 -> 20 | V7: =G7+Q7-K7-N7 -> 0 | W7: =IF(MIN(T7,U7,V7)<0,"NEGATIVE STOCK - CHECK ENTRIES","") | X7: 0 | Y7: 0 | Z7: =X7-Y7 -> 0 | AA7: 0 | AB7: 0 | AC7: =AA7-AB7 -> 0 | AD7: 0 | AE7: 0 | AF7: =AD7-AE7 -> 0 | AG7: 0 | AH7: 0 | AI7: =AG7-AH7 -> 0
A8: African eggplant LIMPOPO RZ F3 | B8: 100 | C8: SEED | D8: COMMERCIAL | E8: ='26 june'!T8 -> 0 | F8: ='26 june'!U8 -> 17 | G8: ='26 june'!V8 -> 20 | H8: =E8+F8+G8 -> 37 | I8: 0 | J8: 0 | K8: 1 | L8: 0 | M8: 0 | N8: 0 | O8: 0 | P8: 0 | Q8: 0 | R8: 0 | S8: =H8+O8+P8+Q8+R8-(I8+J8+K8+L8+M8+N8) -> 36 | T8: =E8+O8-I8-L8 -> 0 | U8: =F8+P8-J8-M8 -> 17 | V8: =G8+Q8-K8-N8 -> 19 | W8: =IF(MIN(T8,U8,V8)<0,"NEGATIVE STOCK - CHECK ENTRIES","") | X8: 0 | Y8: 0 | Z8: =X8-Y8 -> 0 | AA8: 0 | AB8: 0 | AC8: =AA8-AB8 -> 0 | AD8: 0 | AE8: 0 | AF8: =AD8-AE8 -> 0 | AG8: 0 | AH8: 0 | AI8: =AG8-AH8 -> 0
A9: African hot pepper AFADJA RZ F7 | B9: 100 | C9: SEED | D9: COMMERCIAL | E9: ='26 june'!T9 -> 0 | F9: ='26 june'!U9 -> 0 | G9: ='26 june'!V9 -> 1 | H9: =E9+F9+G9 -> 1 | I9: 0 | J9: 0 | K9: 0 | L9: 0 | M9: 0 | N9: 0 | O9: 0 | P9: 0 | Q9: 0 | R9: 0 | S9: =H9+O9+P9+Q9+R9-(I9+J9+K9+L9+M9+N9) -> 1 | T9: =E9+O9-I9-L9 -> 0 | U9: =F9+P9-J9-M9 -> 0 | V9: =G9+Q9-K9-N9 -> 1 | W9: =IF(MIN(T9,U9,V9)<0,"NEGATIVE STOCK - CHECK ENTRIES","") | X9: 0 | Y9: 0 | Z9: =X9-Y9 -> 0 | AA9: 0 | AB9: 0 | AC9: =AA9-AB9 -> 0 | AD9: 0 | AE9: 0 | AF9: =AD9-AE9 -> 0 | AG9: 0 | AH9: 0 | AI9: =AG9-AH9 -> 0
A10: African hot pepper AFADJA RZ F7 | B10: 500 | C10: SEED | D10: COMMERCIAL | E10: ='26 june'!T10 -> 0 | F10: ='26 june'!U10 -> 0 | G10: ='26 june'!V10 -> 0 | H10: =E10+F10+G10 -> 0 | I10: 0 | J10: 0 | K10: 0 | L10: 2 | M10: 0 | N10: 0 | O10: 0 | P10: 0 | Q10: 0 | R10: 0 | S10: =H10+O10+P10+Q10+R10-(I10+J10+K10+L10+M10+N10) -> -2 | T10: =E10+O10-I10-L10 -> -2 | U10: =F10+P10-J10-M10 -> 0 | V10: =G10+Q10-K10-N10 -> 0 | W10: =IF(MIN(T10,U10,V10)<0,"NEGATIVE STOCK - CHECK ENTRIES","") -> NEGATIVE STOCK - CHECK ENTRIES | X10: 0 | Y10: 0 | Z10: =X10-Y10 -> 0 | AA10: 0 | AB10: 0 | AC10: =AA10-AB10 -> 0 | AD10: 0 | AE10: 0 | AF10: =AD10-AE10 -> 0 | AG10: 0 | AH10: 0 | AI10: =AG10-AH10 -> 0
A11: African hot pepper LENGAI RZ F2 | B11: 100 | C11: SEED | D11: COMMERCIAL | E11: ='26 june'!T11 -> 329 | F11: ='26 june'!U11 -> 195 | G11: ='26 june'!V11 -> 16 | H11: =E11+F11+G11 -> 540 | I11: 0 | J11: 0 | K11: 0 | L11: 7 | M11: 0 | N11: 0 | O11: 0 | P11: 0 | Q11: 0 | R11: 0 | S11: =H11+O11+P11+Q11+R11-(I11+J11+K11+L11+M11+N11) -> 533 | T11: =E11+O11-I11-L11 -> 322 | U11: =F11+P11-J11-M11 -> 195 | V11: =G11+Q11-K11-N11 -> 16 | W11: =IF(MIN(T11,U11,V11)<0,"NEGATIVE STOCK - CHECK ENTRIES","") | X11: 0 | Y11: 0 | Z11: =X11-Y11 -> 0 | AA11: 0 | AB11: 0 | AC11: =AA11-AB11 -> 0 | AD11: 0 | AE11: 0 | AF11: =AD11-AE11 -> 0 | AG11: 0 | AH11: 0 | AI11: =AG11-AH11 -> 0
A12: African hot pepper LENGAI RZ F3 | B12: 500 | C12: SEED | D12: COMMERCIAL | E12: ='26 june'!T12 -> 8 | F12: ='26 june'!U12 -> 0 | G12: ='26 june'!V12 -> 0 | H12: =E12+F12+G12 -> 8 | I12: 0 | J12: 0 | K12: 0 | L12: 0 | M12: 0 | N12: 0 | O12: 0 | P12: 0 | Q12: 0 | R12: 0 | S12: =H12+O12+P12+Q12+R12-(I12+J12+K12+L12+M12+N12) -> 8 | T12: =E12+O12-I12-L12 -> 8 | U12: =F12+P12-J12-M12 -> 0 | V12: =G12+Q12-K12-N12 -> 0 | W12: =IF(MIN(T12,U12,V12)<0,"NEGATIVE STOCK - CHECK ENTRIES","") | X12: 0 | Y12: 0 | Z12: =X12-Y12 -> 0 | AA12: 0 | AB12: 0 | AC12: =AA12-AB12 -> 0 | AD12: 0 | AE12: 0 | AF12: =AD12-AE12 -> 0 | AG12: 0 | AH12: 0 | AI12: =AG12-AH12 -> 0
A13: African Hot Pepper Loleza RZ | B13: 100 | C13: SEED | D13: COMMERCIAL | E13: ='26 june'!T13 -> 1504 | F13: ='26 june'!U13 -> 297 | G13: ='26 june'!V13 -> 150 | H13: =E13+F13+G13 -> 1951 | I13: 20 | J13: 200 | K13: 31 | L13: 232 | M13: 0 | N13: 0 | O13: 0 | P13: 200 | Q13: 0 | R13: 0 | S13: =H13+O13+P13+Q13+R13-(I13+J13+K13+L13+M13+N13) -> 1668 | T13: =E13+O13-I13-L13 -> 1252 | U13: =F13+P13-J13-M13 -> 297 | V13: =G13+Q13-K13-N13 -> 119 | W13: =IF(MIN(T13,U13,V13)<0,"NEGATIVE STOCK - CHECK ENTRIES","") | X13: 0 | Y13: 0 | Z13: =X13-Y13 -> 0 | AA13: 0 | AB13: 0 | AC13: =AA13-AB13 -> 0 | AD13: 0 | AE13: 0 | AF13: =AD13-AE13 -> 0 | AG13: 0 | AH13: 0 | AI13: =AG13-AH13 -> 0
A14: African Hot Pepper Loleza RZ | B14: 500 | C14: SEED | D14: COMMERCIAL | E14: ='26 june'!T14 -> 170 | F14: ='26 june'!U14 -> 20 | G14: ='26 june'!V14 -> 15 | H14: =E14+F14+G14 -> 205 | I14: 0 | J14: 20 | K14: 0 | L14: 69 | M14: 0 | N14: 0 | O14: 0 | P14: 60 | Q14: 0 | R14: 0 | S14: =H14+O14+P14+Q14+R14-(I14+J14+K14+L14+M14+N14) -> 176 | T14: =E14+O14-I14-L14 -> 101 | U14: =F14+P14-J14-M14 -> 60 | V14: =G14+Q14-K14-N14 -> 15 | W14: =IF(MIN(T14,U14,V14)<0,"NEGATIVE STOCK - CHECK ENTRIES","") | X14: 0 | Y14: 0 | Z14: =X14-Y14 -> 0 | AA14: 0 | AB14: 0 | AC14: =AA14-AB14 -> 0 | AD14: 0 | AE14: 0 | AF14: =AD14-AE14 -> 0 | AG14: 0 | AH14: 0 | AI14: =AG14-AH14 -> 0
A15: African Hot Pepper Mawenzili | B15: 100 | C15: SEED | D15: COMMERCIAL | E15: ='26 june'!T15 -> 302 | F15: ='26 june'!U15 -> 41 | G15: ='26 june'!V15 -> 11 | H15: =E15+F15+G15 -> 354 | I15: 0 | J15: 0 | K15: 0 | L15: 0 | M15: 0 | N15: 0 | O15: 0 | P15: 0 | Q15: 0 | R15: 0 | S15: =H15+O15+P15+Q15+R15-(I15+J15+K15+L15+M15+N15) -> 354 | T15: =E15+O15-I15-L15 -> 302 | U15: =F15+P15-J15-M15 -> 41 | V15: =G15+Q15-K15-N15 -> 11 | W15: =IF(MIN(T15,U15,V15)<0,"NEGATIVE STOCK - CHECK ENTRIES","") | X15: 0 | Y15: 0 | Z15: =X15-Y15 -> 0 | AA15: 0 | AB15: 0 | AC15: =AA15-AB15 -> 0 | AD15: 0 | AE15: 0 | AF15: =AD15-AE15 -> 0 | AG15: 0 | AH15: 0 | AI15: =AG15-AH15 -> 0
A16: African Hot Pepper Mawenzili | B16: 1000 | C16: SEED | D16: COMMERCIAL | E16: ='26 june'!T16 -> 2 | F16: ='26 june'!U16 -> 0 | G16: ='26 june'!V16 -> 0 | H16: =E16+F16+G16 -> 2 | I16: 1 | J16: 0 | K16: 0 | L16: 0 | M16: 0 | N16: 0 | O16: 0 | P16: 0 | Q16: 0 | R16: 0 | S16: =H16+O16+P16+Q16+R16-(I16+J16+K16+L16+M16+N16) -> 1 | T16: =E16+O16-I16-L16 -> 1 | U16: =F16+P16-J16-M16 -> 0 | V16: =G16+Q16-K16-N16 -> 0 | W16: =IF(MIN(T16,U16,V16)<0,"NEGATIVE STOCK - CHECK ENTRIES","") | X16: 0 | Y16: 0 | Z16: =X16-Y16 -> 0 | AA16: 0 | AB16: 0 | AC16: =AA16-AB16 -> 0 | AD16: 0 | AE16: 0 | AF16: =AD16-AE16 -> 0 | AG16: 0 | AH16: 0 | AI16: =AG16-AH16 -> 0
A17: alaine | B17: 1000 | C17: SEED | D17: MASIFIO CUSTOM | E17: 0 | F17: 0 | G17: 0 | H17: =E17+F17+G17 -> 0 | I17: 0 | J17: 0 | K17: 0 | L17: 0 | M17: 0 | N17: 0 | O17: 0 | P17: 0 | Q17: 0 | R17: 0 | S17: =H17+O17+P17+Q17+R17-(I17+J17+K17+L17+M17+N17) -> 0 | T17: =E17+O17-I17-L17 -> 0 | U17: =F17+P17-J17-M17 -> 0 | V17: =G17+Q17-K17-N17 -> 0 | W17: =IF(MIN(T17,U17,V17)<0,"NEGATIVE STOCK - CHECK ENTRIES","") | X17: 0 | Y17: 0 | Z17: =X17-Y17 -> 0 | AA17: 0 | AB17: 0 | AC17: =AA17-AB17 -> 0 | AD17: 0 | AE17: 0 | AF17: =AD17-AE17 -> 0 | AG17: 0 | AH17: 0 | AI17: =AG17-AH17 -> 0
A18: Alboreto | B18: 100000 | C18: SEED | D18: MASIFIO CUSTOM | E18: 0 | F18: 0 | G18: 0 | H18: =E18+F18+G18 -> 0 | I18: 0 | J18: 0 | K18: 0 | L18: 0 | M18: 0 | N18: 0 | O18: 0 | P18: 0 | Q18: 0 | R18: 0 | S18: =H18+O18+P18+Q18+R18-(I18+J18+K18+L18+M18+N18) -> 0 | T18: =E18+O18-I18-L18 -> 0 | U18: =F18+P18-J18-M18 -> 0 | V18: =G18+Q18-K18-N18 -> 0 | W18: =IF(MIN(T18,U18,V18)<0,"NEGATIVE STOCK - CHECK ENTRIES","") | X18: 0 | Y18: 0 | Z18: =X18-Y18 -> 0 | AA18: 0 | AB18: 0 | AC18: =AA18-AB18 -> 0 | AD18: 0 | AE18: 0 | AF18: =AD18-AE18 -> 0 | AG18: 0 | AH18: 0 | AI18: =AG18-AH18 -> 0
A19: Allegreto | B19: 1000 | C19: SEED | D19: COMMERCIAL | E19: ='26 june'!T19 -> 8 | F19: ='26 june'!U19 -> 0 | G19: ='26 june'!V19 -> 0 | H19: =E19+F19+G19 -> 8 | I19: 0 | J19: 0 | K19: 0 | L19: 0 | M19: 0 | N19: 0 | O19: 0 | P19: 0 | Q19: 0 | R19: 0 | S19: =H19+O19+P19+Q19+R19-(I19+J19+K19+L19+M19+N19) -> 8 | T19: =E19+O19-I19-L19 -> 8 | U19: =F19+P19-J19-M19 -> 0 | V19: =G19+Q19-K19-N19 -> 0 | W19: =IF(MIN(T19,U19,V19)<0,"NEGATIVE STOCK - CHECK ENTRIES","") | X19: 0 | Y19: 0 | Z19: =X19-Y19 -> 0 | AA19: 0 | AB19: 0 | AC19: =AA19-AB19 -> 0 | AD19: 0 | AE19: 0 | AF19: =AD19-AE19 -> 0 | AG19: 0 | AH19: 0 | AI19: =AG19-AH19 -> 0
A20: Allegreto | B20: 1000 | C20: SEED | D20: CUSTOM&TRIAL | E20: 0 | F20: 0 | G20: 0 | H20: =E20+F20+G20 -> 0 | I20: 0 | J20: 0 | K20: 0 | L20: 0 | M20: 0 | N20: 0 | O20: 0 | P20: 0 | Q20: 0 | R20: 0 | S20: =H20+O20+P20+Q20+R20-(I20+J20+K20+L20+M20+N20) -> 0 | T20: =E20+O20-I20-L20 -> 0 | U20: =F20+P20-J20-M20 -> 0 | V20: =G20+Q20-K20-N20 -> 0 | W20: =IF(MIN(T20,U20,V20)<0,"NEGATIVE STOCK - CHECK ENTRIES","") | X20: 0 | Y20: 0 | Z20: =X20-Y20 -> 0 | AA20: 0 | AB20: 0 | AC20: =AA20-AB20 -> 0 | AD20: 0 | AE20: 0 | AF20: =AD20-AE20 -> 0 | AG20: 0 | AH20: 0 | AI20: =AG20-AH20 -> 0
A21: Alpes | B21: 100 | C21: SEED | D21: COMMERCIAL | E21: ='26 june'!T21 -> 4 | F21: ='26 june'!U21 -> 0 | G21: ='26 june'!V21 -> 0 | H21: =E21+F21+G21 -> 4 | I21: 0 | J21: 0 | K21: 0 | L21: 0 | M21: 0 | N21: 0 | O21: 0 | P21: 0 | Q21: 0 | R21: 0 | S21: =H21+O21+P21+Q21+R21-(I21+J21+K21+L21+M21+N21) -> 4 | T21: =E21+O21-I21-L21 -> 4 | U21: =F21+P21-J21-M21 -> 0 | V21: =G21+Q21-K21-N21 -> 0 | W21: =IF(MIN(T21,U21,V21)<0,"NEGATIVE STOCK - CHECK ENTRIES","") | X21: 0 | Y21: 0 | Z21: =X21-Y21 -> 0 | AA21: 0 | AB21: 0 | AC21: =AA21-AB21 -> 0 | AD21: 0 | AE21: 0 | AF21: =AD21-AE21 -> 0 | AG21: 0 | AH21: 0 | AI21: =AG21-AH21 -> 0
A22: Alpes | B22: 1000 | C22: SEED | D22: COMMERCIAL | E22: ='26 june'!T22 -> 8 | F22: ='26 june'!U22 -> 0 | G22: ='26 june'!V22 -> 0 | H22: =E22+F22+G22 -> 8 | I22: 0 | J22: 0 | K22: 0 | L22: 0 | M22: 0 | N22: 0 | O22: 0 | P22: 0 | Q22: 0 | R22: 0 | S22: =H22+O22+P22+Q22+R22-(I22+J22+K22+L22+M22+N22) -> 8 | T22: =E22+O22-I22-L22 -> 8 | U22: =F22+P22-J22-M22 -> 0 | V22: =G22+Q22-K22-N22 -> 0 | W22: =IF(MIN(T22,U22,V22)<0,"NEGATIVE STOCK - CHECK ENTRIES","") | X22: 0 | Y22: 0 | Z22: =X22-Y22 -> 0 | AA22: 0 | AB22: 0 | AC22: =AA22-AB22 -> 0 | AD22: 0 | AE22: 0 | AF22: =AD22-AE22 -> 0 | AG22: 0 | AH22: 0 | AI22: =AG22-AH22 -> 0
A23: amburana | B23: 100 | C23: SEED | D23: CUSTOM&TRIAL | E23: 0 | F23: 0 | G23: 0 | H23: =E23+F23+G23 -> 0 | I23: 0 | J23: 0 | K23: 0 | L23: 0 | M23: 0 | N23: 0 | O23: 0 | P23: 0 | Q23: 0 | R23: 0 | S23: =H23+O23+P23+Q23+R23-(I23+J23+K23+L23+M23+N23) -> 0 | T23: =E23+O23-I23-L23 -> 0 | U23: =F23+P23-J23-M23 -> 0 | V23: =G23+Q23-K23-N23 -> 0 | W23: =IF(MIN(T23,U23,V23)<0,"NEGATIVE STOCK - CHECK ENTRIES","") | X23: 0 | Y23: 0 | Z23: =X23-Y23 -> 0 | AA23: 0 | AB23: 0 | AC23: =AA23-AB23 -> 0 | AD23: 0 | AE23: 0 | AF23: =AD23-AE23 -> 0 | AG23: 0 | AH23: 0 | AI23: =AG23-AH23 -> 0
A24: amburana | B24: 500 | C24: SEED | D24: CUSTOM&TRIAL | E24: 0 | F24: 0 | G24: 0 | H24: =E24+F24+G24 -> 0 | I24: 0 | J24: 0 | K24: 0 | L24: 0 | M24: 0 | N24: 0 | O24: 0 | P24: 0 | Q24: 0 | R24: 0 | S24: =H24+O24+P24+Q24+R24-(I24+J24+K24+L24+M24+N24) -> 0 | T24: =E24+O24-I24-L24 -> 0 | U24: =F24+P24-J24-M24 -> 0 | V24: =G24+Q24-K24-N24 -> 0 | W24: =IF(MIN(T24,U24,V24)<0,"NEGATIVE STOCK - CHECK ENTRIES","") | X24: 0 | Y24: 0 | Z24: =X24-Y24 -> 0 | AA24: 0 | AB24: 0 | AC24: =AA24-AB24 -> 0 | AD24: 0 | AE24: 0 | AF24: =AD24-AE24 -> 0 | AG24: 0 | AH24: 0 | AI24: =AG24-AH24 -> 0
A25: Aubergine BRIGITTE RZ F2 | B25: 100 | C25: SEED | D25: COMMERCIAL | E25: ='26 june'!T25 -> 1 | F25: ='26 june'!U25 -> 151 | G25: ='26 june'!V25 -> 0 | H25: =E25+F25+G25 -> 152 | I25: 0 | J25: 0 | K25: 0 | L25: 0 | M25: 0 | N25: 0 | O25: 0 | P25: 0 | Q25: 0 | R25: 0 | S25: =H25+O25+P25+Q25+R25-(I25+J25+K25+L25+M25+N25) -> 152 | T25: =E25+O25-I25-L25 -> 1 | U25: =F25+P25-J25-M25 -> 151 | V25: =G25+Q25-K25-N25 -> 0 | W25: =IF(MIN(T25,U25,V25)<0,"NEGATIVE STOCK - CHECK ENTRIES","") | X25: 0 | Y25: 0 | Z25: =X25-Y25 -> 0 | AA25: 0 | AB25: 0 | AC25: =AA25-AB25 -> 0 | AD25: 0 | AE25: 0 | AF25: =AD25-AE25 -> 0 | AG25: 0 | AH25: 0 | AI25: =AG25-AH25 -> 0
A26: Aubergine FANTASTIC RZ F3 | B26: 100 | C26: SEED | D26: COMMERCIAL | E26: ='26 june'!T26 -> 89 | F26: ='26 june'!U26 -> 28 | G26: ='26 june'!V26 -> 4 | H26: =E26+F26+G26 -> 121 | I26: 0 | J26: 0 | K26: 0 | L26: 0 | M26: 0 | N26: 0 | O26: 0 | P26: 0 | Q26: 0 | R26: 0 | S26: =H26+O26+P26+Q26+R26-(I26+J26+K26+L26+M26+N26) -> 121 | T26: =E26+O26-I26-L26 -> 89 | U26: =F26+P26-J26-M26 -> 28 | V26: =G26+Q26-K26-N26 -> 4 | W26: =IF(MIN(T26,U26,V26)<0,"NEGATIVE STOCK - CHECK ENTRIES","") | X26: 0 | Y26: 0 | Z26: =X26-Y26 -> 0 | AA26: 0 | AB26: 0 | AC26: =AA26-AB26 -> 0 | AD26: 0 | AE26: 0 | AF26: =AD26-AE26 -> 0 | AG26: 0 | AH26: 0 | AI26: =AG26-AH26 -> 0
A27: barlach | B27: 1000 | C27: SEED | D27: MASIFIO CUSTOM | E27: 0 | F27: 0 | G27: 0 | H27: =E27+F27+G27 -> 0 | I27: 0 | J27: 0 | K27: 0 | L27: 0 | M27: 0 | N27: 0 | O27: 0 | P27: 0 | Q27: 0 | R27: 0 | S27: =H27+O27+P27+Q27+R27-(I27+J27+K27+L27+M27+N27) -> 0 | T27: =E27+O27-I27-L27 -> 0 | U27: =F27+P27-J27-M27 -> 0 | V27: =G27+Q27-K27-N27 -> 0 | W27: =IF(MIN(T27,U27,V27)<0,"NEGATIVE STOCK - CHECK ENTRIES","") | X27: 0 | Y27: 0 | Z27: =X27-Y27 -> 0 | AA27: 0 | AB27: 0 | AC27: =AA27-AB27 -> 0 | AD27: 0 | AE27: 0 | AF27: =AD27-AE27 -> 0 | AG27: 0 | AH27: 0 | AI27: =AG27-AH27 -> 0
A28: Barldralla | B28: 100 | C28: SEED | D28: MASIFIO CUSTOM | E28: 0 | F28: 0 | G28: 0 | H28: =E28+F28+G28 -> 0 | I28: 0 | J28: 0 | K28: 0 | L28: 0 | M28: 0 | N28: 0 | O28: 0 | P28: 0 | Q28: 0 | R28: 0 | S28: =H28+O28+P28+Q28+R28-(I28+J28+K28+L28+M28+N28) -> 0 | T28: =E28+O28-I28-L28 -> 0 | U28: =F28+P28-J28-M28 -> 0 | V28: =G28+Q28-K28-N28 -> 0 | W28: =IF(MIN(T28,U28,V28)<0,"NEGATIVE STOCK - CHECK ENTRIES","") | X28: 0 | Y28: 0 | Z28: =X28-Y28 -> 0 | AA28: 0 | AB28: 0 | AC28: =AA28-AB28 -> 0 | AD28: 0 | AE28: 0 | AF28: =AD28-AE28 -> 0 | AG28: 0 | AH28: 0 | AI28: =AG28-AH28 -> 0
A29: Baronesa | B29: 100 | C29: SEED | D29: COMMERCIAL | E29: ='26 june'!T29 -> 34 | F29: ='26 june'!U29 -> 0 | G29: ='26 june'!V29 -> 0 | H29: =E29+F29+G29 -> 34 | I29: 0 | J29: 0 | K29: 0 | L29: 0 | M29: 0 | N29: 0 | O29: 0 | P29: 0 | Q29: 0 | R29: 0 | S29: =H29+O29+P29+Q29+R29-(I29+J29+K29+L29+M29+N29) -> 34 | T29: =E29+O29-I29-L29 -> 34 | U29: =F29+P29-J29-M29 -> 0 | V29: =G29+Q29-K29-N29 -> 0 | W29: =IF(MIN(T29,U29,V29)<0,"NEGATIVE STOCK - CHECK ENTRIES","") | X29: 0 | Y29: 0 | Z29: =X29-Y29 -> 0 | AA29: 0 | AB29: 0 | AC29: =AA29-AB29 -> 0 | AD29: 0 | AE29: 0 | AF29: =AD29-AE29 -> 0 | AG29: 0 | AH29: 0 | AI29: =AG29-AH29 -> 0
A30: Batavia lettuce INVICTA RZ | B30: 1000 | C30: SEED | D30: COMMERCIAL | E30: ='26 june'!T30 -> 4 | F30: ='26 june'!U30 -> 7 | G30: ='26 june'!V30 -> 35 | H30: =E30+F30+G30 -> 46 | I30: 4 | J30: 0 | K30: 10 | L30: 0 | M30: 0 | N30: 0 | O30: 0 | P30: 0 | Q30: 0 | R30: 0 | S30: =H30+O30+P30+Q30+R30-(I30+J30+K30+L30+M30+N30) -> 32 | T30: =E30+O30-I30-L30 -> 0 | U30: =F30+P30-J30-M30 -> 7 | V30: =G30+Q30-K30-N30 -> 25 | W30: =IF(MIN(T30,U30,V30)<0,"NEGATIVE STOCK - CHECK ENTRIES","") | X30: 0 | Y30: 0 | Z30: =X30-Y30 -> 0 | AA30: 0 | AB30: 0 | AC30: =AA30-AB30 -> 0 | AD30: 0 | AE30: 0 | AF30: =AD30-AE30 -> 0 | AG30: 0 | AH30: 0 | AI30: =AG30-AH30 -> 0
A31: Batavia lettuce TOURBILLON RZ | B31: 1000 | C31: SEED | D31: COMMERCIAL | E31: ='26 june'!T31 -> 9 | F31: ='26 june'!U31 -> 5 | G31: ='26 june'!V31 -> 27 | H31: =E31+F31+G31 -> 41 | I31: 0 | J31: 0 | K31: 0 | L31: 0 | M31: 0 | N31: 0 | O31: 0 | P31: 0 | Q31: 0 | R31: 0 | S31: =H31+O31+P31+Q31+R31-(I31+J31+K31+L31+M31+N31) -> 41 | T31: =E31+O31-I31-L31 -> 9 | U31: =F31+P31-J31-M31 -> 5 | V31: =G31+Q31-K31-N31 -> 27 | W31: =IF(MIN(T31,U31,V31)<0,"NEGATIVE STOCK - CHECK ENTRIES","") | X31: 0 | Y31: 0 | Z31: =X31-Y31 -> 0 | AA31: 0 | AB31: 0 | AC31: =AA31-AB31 -> 0 | AD31: 0 | AE31: 0 | AF31: =AD31-AE31 -> 0 | AG31: 0 | AH31: 0 | AI31: =AG31-AH31 -> 0
A32: Beetroot LARKA RZ | B32: 25000 | C32: SEED | D32: COMMERCIAL | E32: ='26 june'!T32 -> 4 | F32: ='26 june'!U32 -> 0 | G32: ='26 june'!V32 -> 0 | H32: =E32+F32+G32 -> 4 | I32: 0 | J32: 0 | K32: 0 | L32: 0 | M32: 0 | N32: 0 | O32: 0 | P32: 0 | Q32: 0 | R32: 0 | S32: =H32+O32+P32+Q32+R32-(I32+J32+K32+L32+M32+N32) -> 4 | T32: =E32+O32-I32-L32 -> 4 | U32: =F32+P32-J32-M32 -> 0 | V32: =G32+Q32-K32-N32 -> 0 | W32: =IF(MIN(T32,U32,V32)<0,"NEGATIVE STOCK - CHECK ENTRIES","") | X32: 0 | Y32: 0 | Z32: =X32-Y32 -> 0 | AA32: 0 | AB32: 0 | AC32: =AA32-AB32 -> 0 | AD32: 0 | AE32: 0 | AF32: =AD32-AE32 -> 0 | AG32: 0 | AH32: 0 | AI32: =AG32-AH32 -> 0
A33: Beetroot Zeppo | B33: 25000 | C33: SEED | D33: COMMERCIAL | E33: ='26 june'!T33 -> 10 | F33: ='26 june'!U33 -> 0 | G33: ='26 june'!V33 -> 0 | H33: =E33+F33+G33 -> 10 | I33: 0 | J33: 0 | K33: 0 | L33: 0 | M33: 0 | N33: 0 | O33: 0 | P33: 0 | Q33: 0 | R33: 0 | S33: =H33+O33+P33+Q33+R33-(I33+J33+K33+L33+M33+N33) -> 10 | T33: =E33+O33-I33-L33 -> 10 | U33: =F33+P33-J33-M33 -> 0 | V33: =G33+Q33-K33-N33 -> 0 | W33: =IF(MIN(T33,U33,V33)<0,"NEGATIVE STOCK - CHECK ENTRIES","") | X33: 0 | Y33: 0 | Z33: =X33-Y33 -> 0 | AA33: 0 | AB33: 0 | AC33: =AA33-AB33 -> 0 | AD33: 0 | AE33: 0 | AF33: =AD33-AE33 -> 0 | AG33: 0 | AH33: 0 | AI33: =AG33-AH33 -> 0
A34: Bellaire | B34: 1000 | C34: SEED | D34: MASIFIO CUSTOM | E34: 0 | F34: 0 | G34: 0 | H34: =E34+F34+G34 -> 0 | I34: 0 | J34: 0 | K34: 0 | L34: 0 | M34: 0 | N34: 0 | O34: 0 | P34: 0 | Q34: 0 | R34: 0 | S34: =H34+O34+P34+Q34+R34-(I34+J34+K34+L34+M34+N34) -> 0 | T34: =E34+O34-I34-L34 -> 0 | U34: =F34+P34-J34-M34 -> 0 | V34: =G34+Q34-K34-N34 -> 0 | W34: =IF(MIN(T34,U34,V34)<0,"NEGATIVE STOCK - CHECK ENTRIES","") | X34: 0 | Y34: 0 | Z34: =X34-Y34 -> 0 | AA34: 0 | AB34: 0 | AC34: =AA34-AB34 -> 0 | AD34: 0 | AE34: 0 | AF34: =AD34-AE34 -> 0 | AG34: 0 | AH34: 0 | AI34: =AG34-AH34 -> 0
A35: benue | B35: 100 | C35: SEED | D35: CUSTOM&TRIAL | E35: 0 | F35: 0 | G35: 0 | H35: =E35+F35+G35 -> 0 | I35: 0 | J35: 0 | K35: 0 | L35: 0 | M35: 0 | N35: 0 | O35: 0 | P35: 0 | Q35: 0 | R35: 0 | S35: =H35+O35+P35+Q35+R35-(I35+J35+K35+L35+M35+N35) -> 0 | T35: =E35+O35-I35-L35 -> 0 | U35: =F35+P35-J35-M35 -> 0 | V35: =G35+Q35-K35-N35 -> 0 | W35: =IF(MIN(T35,U35,V35)<0,"NEGATIVE STOCK - CHECK ENTRIES","") | X35: 0 | Y35: 0 | Z35: =X35-Y35 -> 0 | AA35: 0 | AB35: 0 | AC35: =AA35-AB35 -> 0 | AD35: 0 | AE35: 0 | AF35: =AD35-AE35 -> 0 | AG35: 0 | AH35: 0 | AI35: =AG35-AH35 -> 0
A36: Blanched celery KYLIAN RZ | B36: 1000 | C36: SEED | D36: COMMERCIAL | E36: ='26 june'!T36 -> 0 | F36: ='26 june'!U36 -> 0 | G36: ='26 june'!V36 -> 0 | H36: =E36+F36+G36 -> 0 | I36: 0 | J36: 0 | K36: 0 | L36: 0 | M36: 0 | N36: 0 | O36: 0 | P36: 0 | Q36: 0 | R36: 0 | S36: =H36+O36+P36+Q36+R36-(I36+J36+K36+L36+M36+N36) -> 0 | T36: =E36+O36-I36-L36 -> 0 | U36: =F36+P36-J36-M36 -> 0 | V36: =G36+Q36-K36-N36 -> 0 | W36: =IF(MIN(T36,U36,V36)<0,"NEGATIVE STOCK - CHECK ENTRIES","") | X36: 0 | Y36: 0 | Z36: =X36-Y36 -> 0 | AA36: 0 | AB36: 0 | AC36: =AA36-AB36 -> 0 | AD36: 0 | AE36: 0 | AF36: =AD36-AE36 -> 0 | AG36: 0 | AH36: 0 | AI36: =AG36-AH36 -> 0
A37: Boelli | B37: 1000 | C37: SEED | D37: MASIFIO CUSTOM | E37: 0 | F37: 0 | G37: 0 | H37: =E37+F37+G37 -> 0 | I37: 0 | J37: 0 | K37: 0 | L37: 0 | M37: 0 | N37: 0 | O37: 0 | P37: 0 | Q37: 0 | R37: 0 | S37: =H37+O37+P37+Q37+R37-(I37+J37+K37+L37+M37+N37) -> 0 | T37: =E37+O37-I37-L37 -> 0 | U37: =F37+P37-J37-M37 -> 0 | V37: =G37+Q37-K37-N37 -> 0 | W37: =IF(MIN(T37,U37,V37)<0,"NEGATIVE STOCK - CHECK ENTRIES","") | X37: 0 | Y37: 0 | Z37: =X37-Y37 -> 0 | AA37: 0 | AB37: 0 | AC37: =AA37-AB37 -> 0 | AD37: 0 | AE37: 0 | AF37: =AD37-AE37 -> 0 | AG37: 0 | AH37: 0 | AI37: =AG37-AH37 -> 0
A38: Bologna | B38: 100 | C38: SEED | D38: CUSTOM&TRIAL | E38: 0 | F38: 0 | G38: 0 | H38: =E38+F38+G38 -> 0 | I38: 0 | J38: 0 | K38: 0 | L38: 0 | M38: 0 | N38: 0 | O38: 0 | P38: 0 | Q38: 0 | R38: 0 | S38: =H38+O38+P38+Q38+R38-(I38+J38+K38+L38+M38+N38) -> 0 | T38: =E38+O38-I38-L38 -> 0 | U38: =F38+P38-J38-M38 -> 0 | V38: =G38+Q38-K38-N38 -> 0 | W38: =IF(MIN(T38,U38,V38)<0,"NEGATIVE STOCK - CHECK ENTRIES","") | X38: 0 | Y38: 0 | Z38: =X38-Y38 -> 0 | AA38: 0 | AB38: 0 | AC38: =AA38-AB38 -> 0 | AD38: 0 | AE38: 0 | AF38: =AD38-AE38 -> 0 | AG38: 0 | AH38: 0 | AI38: =AG38-AH38 -> 0
A39: Bottas | B39: 100000 | C39: SEED | D39: MASIFIO CUSTOM | E39: 0 | F39: 0 | G39: 0 | H39: =E39+F39+G39 -> 0 | I39: 0 | J39: 0 | K39: 0 | L39: 0 | M39: 0 | N39: 0 | O39: 0 | P39: 0 | Q39: 0 | R39: 0 | S39: =H39+O39+P39+Q39+R39-(I39+J39+K39+L39+M39+N39) -> 0 | T39: =E39+O39-I39-L39 -> 0 | U39: =F39+P39-J39-M39 -> 0 | V39: =G39+Q39-K39-N39 -> 0 | W39: =IF(MIN(T39,U39,V39)<0,"NEGATIVE STOCK - CHECK ENTRIES","") | X39: 0 | Y39: 0 | Z39: =X39-Y39 -> 0 | AA39: 0 | AB39: 0 | AC39: =AA39-AB39 -> 0 | AD39: 0 | AE39: 0 | AF39: =AD39-AE39 -> 0 | AG39: 0 | AH39: 0 | AI39: =AG39-AH39 -> 0
